Workbook
Name Slicer_Ability1: #N/A
Name Slicer_Ability2: #N/A
Name Slicer_HiddenAbility: #N/A

Sheet DUMP
A1: # See the documentation on the wiki to learn how to edit this file.
A2: #-------------------------------
A3: [KOFFING] | E3: =A3&","&A4&","&A5&","&A6&","&A7&","&A8&","&A9&","&A10&","&A11&","&A12&","&A13&","&A14&","&A15&","&A16&","&A17&","&A18&","&A19&","&A20&","&A21&","&A22&","&A23&","&A24&","&A25&","&A26&","&A27 -> [KOFFING],Name = Koffing,Types = FIRE,BaseStats = 60,50,45,35,65,85,GenderRatio = Female50Percent,GrowthRate = Medium,BaseExp = 68,EVs = SPECIAL_DEFENSE,1,CatchRate = 190,Happiness = 70,Abilities = LEVITATE,WHITESMOKE,HiddenAbilities = FILTER,Moves = 1,POISONGAS,1,DEFENSECURL,5,EMBER,9,SMOG,12,HAZE,16,INCINERATE,19,CLEARSMOG,22,GYROBALL,26,CORRODE,30,SUNNYDAY,34,LAVAPLUME,38,DESTINYBOND,42,CORROSIVEGAS,45,ACIDRAIN,49,MEMENTO,54,ERUPTION,TutorMoves = TOXIC,HIDDENPOWER,SUNNYDAY,PROTECT,FRUSTRATION,RETURN,REFLECT,SLUDGEWAVE,FLAMETHROWER,SLUDGEBOMB,FIREBLAST,FACADE,REST,ATTRACT,OVERHEAT,SCALD,INCINERATE,WILLOWISP,EXPLOSION,SUBSTITUTE,HEATWAVE,SLEEPTALK,WEATHERBALL,FIRESPIN,CHARGEBEAM,SOLARBEAM,SOLARBLADE,MUDSHACKLES,STEALTHROCK,BEATUP,ALLERGY,ACIDRAIN,GASTROACID,ACIDARMOR,HEX,CURSE,CONFUSERAY,OMINOUSWIND,METEORDRIVE,GAMMARAY,GRAVITY,ROUND,ECHOEDVOICE,SCHIZOPHRENIA,RAYOFLIGHT,SIGNALBEAM,BODYSLAM,BALANCERCHANGEREQUIRED,NASTYPLOT,GUNKSHOT,SHADOWBALL,GYROBALL,BEJEWELED,POWERGEM,BURNINGJEALOUSY,FIREPLEDGE,SHOCKWAVE,SCORCHINGSANDS,STEAMROLLER,ZENHEADBUTT,TWINBEAM,WORKUP,CORROSIVEGAS,VITALITYDRAIN,MEMENTO,GRUDGE,BODYPRESS,TIMEBOMB,DEFOG,WAIL,COUPDEGRACE,ANCIENTPOWER,GLISTEN,TOXICSPIKES,EggMoves = CURSE,HEATCRASH,SLUDGEBOMB,BALANCERCHANGEREQUIRED,SIZZLE,FIERYDANCE,EggGroups = Amorphous,HatchSteps = 5355,Height = 0.6,Weight = 1.0,Color = Red,Shape = Head,Category = Volcanic Gas,Pokedex = The result of unifying poisonous gas, steam and a superheated atmosphere. Highly volatile, these Koffing are capable of spewing fireballs.,Generation = 1,Evolutions = WEEZING,LevelDay,33
A4: Name = Koffing
A5: Types = FIRE
A6: BaseStats = 60,50,45,35,65,85
A7: GenderRatio = Female50Percent
A8: GrowthRate = Medium
A9: BaseExp = 68
A10: EVs = SPECIAL_DEFENSE,1
A11: CatchRate = 190
A12: Happiness = 70
A13: Abilities = LEVITATE,WHITESMOKE
A14: HiddenAbilities = FILTER
A15: Moves = 1,POISONGAS,1,DEFENSECURL,5,EMBER,9,SMOG,12,HAZE,16,INCINERATE,19,CLEARSMOG,22,GYROBALL,26,CORRODE,30,SUNNYDAY,34,LAVAPLUME,38,DESTINYBOND,42,CORROSIVEGAS,45,ACIDRAIN,49,MEMENTO,54,ERUPTION | E15: =A15&","&A16&","&A17&","&A18&","&A19&","&A20&","&A21&","&A22&","&A23&","&A24&","&A25&","&A26&","&A27 -> Moves = 1,POISONGAS,1,DEFENSECURL,5,EMBER,9,SMOG,12,HAZE,16,INCINERATE,19,CLEARSMOG,22,GYROBALL,26,CORRODE,30,SUNNYDAY,34,LAVAPLUME,38,DESTINYBOND,42,CORROSIVEGAS,45,ACIDRAIN,49,MEMENTO,54,ERUPTION,TutorMoves = TOXIC,HIDDENPOWER,SUNNYDAY,PROTECT,FRUSTRATION,RETURN,REFLECT,SLUDGEWAVE,FLAMETHROWER,SLUDGEBOMB,FIREBLAST,FACADE,REST,ATTRACT,OVERHEAT,SCALD,INCINERATE,WILLOWISP,EXPLOSION,SUBSTITUTE,HEATWAVE,SLEEPTALK,WEATHERBALL,FIRESPIN,CHARGEBEAM,SOLARBEAM,SOLARBLADE,MUDSHACKLES,STEALTHROCK,BEATUP,ALLERGY,ACIDRAIN,GASTROACID,ACIDARMOR,HEX,CURSE,CONFUSERAY,OMINOUSWIND,METEORDRIVE,GAMMARAY,GRAVITY,ROUND,ECHOEDVOICE,SCHIZOPHRENIA,RAYOFLIGHT,SIGNALBEAM,BODYSLAM,BALANCERCHANGEREQUIRED,NASTYPLOT,GUNKSHOT,SHADOWBALL,GYROBALL,BEJEWELED,POWERGEM,BURNINGJEALOUSY,FIREPLEDGE,SHOCKWAVE,SCORCHINGSANDS,STEAMROLLER,ZENHEADBUTT,TWINBEAM,WORKUP,CORROSIVEGAS,VITALITYDRAIN,MEMENTO,GRUDGE,BODYPRESS,TIMEBOMB,DEFOG,WAIL,COUPDEGRACE,ANCIENTPOWER,GLISTEN,TOXICSPIKES,EggMoves = CURSE,HEATCRASH,SLUDGEBOMB,BALANCERCHANGEREQUIRED,SIZZLE,FIERYDANCE,EggGroups = Amorphous,HatchSteps = 5355,Height = 0.6,Weight = 1.0,Color = Red,Shape = Head,Category = Volcanic Gas,Pokedex = The result of unifying poisonous gas, steam and a superheated atmosphere. Highly volatile, these Koffing are capable of spewing fireballs.,Generation = 1,Evolutions = WEEZING,LevelDay,33
A16: TutorMoves = TOXIC,HIDDENPOWER,SUNNYDAY,PROTECT,FRUSTRATION,RETURN,REFLECT,SLUDGEWAVE,FLAMETHROWER,SLUDGEBOMB,FIREBLAST,FACADE,REST,ATTRACT,OVERHEAT,SCALD,INCINERATE,WILLOWISP,EXPLOSION,SUBSTITUTE,HEATWAVE,SLEEPTALK,WEATHERBALL,FIRESPIN,CHARGEBEAM,SOLARBEAM,SOLARBLADE,MUDSHACKLES,STEALTHROCK,BEATUP,ALLERGY,ACIDRAIN,GASTROACID,ACIDARMOR,HEX,CURSE,CONFUSERAY,OMINOUSWIND,METEORDRIVE,GAMMARAY,GRAVITY,ROUND,ECHOEDVOICE,SCHIZOPHRENIA,RAYOFLIGHT,SIGNALBEAM,BODYSLAM,BALANCERCHANGEREQUIRED,NASTYPLOT,GUNKSHOT,SHADOWBALL,GYROBALL,BEJEWELED,POWERGEM,BURNINGJEALOUSY,FIREPLEDGE,SHOCKWAVE,SCORCHINGSANDS,STEAMROLLER,ZENHEADBUTT,TWINBEAM,WORKUP,CORROSIVEGAS,VITALITYDRAIN,MEMENTO,GRUDGE,BODYPRESS,TIMEBOMB,DEFOG,WAIL,COUPDEGRACE,ANCIENTPOWER,GLISTEN,TOXICSPIKES
A17: EggMoves = CURSE,HEATCRASH,SLUDGEBOMB,BALANCERCHANGEREQUIRED,SIZZLE,FIERYDANCE
A18: EggGroups = Amorphous
A19: HatchSteps = 5355
A20: Height = 0.6
A21: Weight = 1.0
A22: Color = Red
A23: Shape = Head
A24: Category = Volcanic Gas
A25: Pokedex = The result of unifying poisonous gas, steam and a superheated atmosphere. Highly volatile, these Koffing are capable of spewing fireballs.
A26: Generation = 1
A27: Evolutions = WEEZING,LevelDay,33
A28: #-------------------------------
A29: [WEEZING] | E29: =A29&","&A30&","&A31&","&A32&","&A33&","&A34&","&A35&","&A36&","&A37&","&A38&","&A39&","&A40&","&A41&","&A42&","&A43&","&A44&","&A45&","&A46&","&A47&","&A48&","&A49&","&A50&","&A51&","&A52&","&A53 -> [WEEZING],Name = Weezing,Types = FIRE,BaseStats = 85,70,70,60,95,110,GenderRatio = Female50Percent,GrowthRate = Medium,BaseExp = 172,EVs = SPECIAL_DEFENSE,2,CatchRate = 100,Happiness = 70,Abilities = LEVITATE,MAGMAARMOR,HiddenAbilities = FILTER,Moves = 0,WILLOWISP,1,WILLOWISP,1,RECOVER,1,POISONGAS,1,DEFENSECURL,5,EMBER,9,SMOG,12,HAZE,16,INCINERATE,19,CLEARSMOG,22,GYROBALL,26,CORRODE,30,SUNNYDAY,36,LAVAPLUME,40,DESTINYBOND,44,CORROSIVEGAS,49,ACIDRAIN,53,MEMENTO,57,ERUPTION,TutorMoves = TOXIC,HIDDENPOWER,SUNNYDAY,PROTECT,FRUSTRATION,RETURN,REFLECT,SLUDGEWAVE,FLAMETHROWER,SLUDGEBOMB,FIREBLAST,FACADE,REST,ATTRACT,OVERHEAT,SCALD,INCINERATE,WILLOWISP,EXPLOSION,SUBSTITUTE,HEATWAVE,SLEEPTALK,WEATHERBALL,FIRESPIN,CHARGEBEAM,SOLARBEAM,SOLARBLADE,MUDSHACKLES,STEALTHROCK,BEATUP,ALLERGY,ACIDRAIN,GASTROACID,ACIDARMOR,HEX,CURSE,CONFUSERAY,OMINOUSWIND,METEORDRIVE,GAMMARAY,GRAVITY,ROUND,ECHOEDVOICE,SCHIZOPHRENIA,RAYOFLIGHT,SIGNALBEAM,BODYSLAM,BALANCERCHANGEREQUIRED,NASTYPLOT,GUNKSHOT,SHADOWBALL,GYROBALL,BEJEWELED,POWERGEM,BURNINGJEALOUSY,FIREPLEDGE,SHOCKWAVE,SCORCHINGSANDS,STEAMROLLER,ZENHEADBUTT,TWINBEAM,WORKUP,CORROSIVEGAS,VITALITYDRAIN,MEMENTO,GRUDGE,BODYPRESS,TIMEBOMB,DEFOG,WAIL,COUPDEGRACE,ANCIENTPOWER,GLISTEN,HYPERBEAM,GIGAIMPACT,TOXICSPIKES,EggGroups = Amorphous,HatchSteps = 5355,Height = 1.2,Weight = 9.5,Color = Red,Shape = Head,Category = Volcanic Gas,Pokedex = The superheated atmosphere of a volcano makes their chemical composition far more unstable and likely to attract more gaseous tumours on its body.,Generation = 1,#-------------------------------,[SOLOSIS]
A30: Name = Weezing
A31: Types = FIRE
A32: BaseStats = 85,70,70,60,95,110
A33: GenderRatio = Female50Percent
A34: GrowthRate = Medium
A35: BaseExp = 172
A36: EVs = SPECIAL_DEFENSE,2
A37: CatchRate = 100
A38: Happiness = 70
A39: Abilities = LEVITATE,MAGMAARMOR
A40: HiddenAbilities = FILTER
...

Sheet Worksheet
A1: ID | B1: Internal Name | C1: Name | D1: Type | E1: BST | F1: HP | G1: Attack | H1: Defense | I1: Speed | J1: SpAtk | K1: SpDef | L1: Gender Ratio | M1: Growth Rate | N1: Base Exp | O1: EVs
B2: [KOFFING],Name = Koffing,Types = FIRE,BaseStats = 60,50,45,35,65,85,GenderRatio = Female50Percent,GrowthRate = Medium,BaseExp = 68,EVs = SPECIAL_DEFENSE,1,CatchRate = 190,Happiness = 70,Abilities = LEVITATE,WHITESMOKE,HiddenAbilities = FILTER,Moves = 1,POISONGAS,1,DEFENSECURL,5,EMBER,9,SMOG,12,HAZE,16,INCINERATE,19,CLEARSMOG,22,GYROBALL,26,CORRODE,30,SUNNYDAY,34,LAVAPLUME,38,DESTINYBOND,42,CORROSIVEGAS,45,ACIDRAIN,49,MEMENTO,54,ERUPTION,TutorMoves = TOXIC,HIDDENPOWER,SUNNYDAY,PROTECT,FRUSTRATION,RETURN,REFLECT,SLUDGEWAVE,FLAMETHROWER,SLUDGEBOMB,FIREBLAST,FACADE,REST,ATTRACT,OVERHEAT,SCALD,INCINERATE,WILLOWISP,EXPLOSION,SUBSTITUTE,HEATWAVE,SLEEPTALK,WEATHERBALL,FIRESPIN,CHARGEBEAM,SOLARBEAM,SOLARBLADE,MUDSHACKLES,STEALTHROCK,BEATUP,ALLERGY,ACIDRAIN,GASTROACID,ACIDARMOR,HEX,CURSE,CONFUSERAY,OMINOUSWIND,METEORDRIVE,GAMMARAY,GRAVITY,ROUND,ECHOEDVOICE,SCHIZOPHRENIA,RAYOFLIGHT,SIGNALBEAM,BODYSLAM,BALANCERCHANGEREQUIRED,NASTYPLOT,GUNKSHOT,SHADOWBALL,GYROBALL,BEJEWELED,POWERGEM,BURNINGJEALOUSY,FIREPLEDGE,SHOCKWAVE,SCORCHINGSANDS,STEAMROLLER,ZENHEADBUTT,TWINBEAM,WORKUP,CORROSIVEGAS,VITALITYDRAIN,MEMENTO,GRUDGE,BODYPRESS,TIMEBOMB,DEFOG,WAIL,COUPDEGRACE,ANCIENTPOWER,GLISTEN,TOXICSPIKES,EggMoves = CURSE,HEATCRASH,SLUDGEBOMB,BALANCERCHANGEREQUIRED,SIZZLE,FIERYDANCE,EggGroups = Amorphous,HatchSteps = 5355,Height = 0.6,Weight = 1.0,Color = Red,Shape = Head,Category = Volcanic Gas,Pokedex = The result of unifying poisonous gas, steam and a superheated atmosphere. Highly volatile, these Koffing are capable of spewing fireballs.,Generation = 1,Evolutions = WEEZING,LevelDay,33
B3: [WEEZING],Name = Weezing,Types = FIRE,BaseStats = 85,70,70,60,95,110,GenderRatio = Female50Percent,GrowthRate = Medium,BaseExp = 172,EVs = SPECIAL_DEFENSE,2,CatchRate = 100,Happiness = 70,Abilities = LEVITATE,MAGMAARMOR,HiddenAbilities = FILTER,Moves = 0,WILLOWISP,1,WILLOWISP,1,RECOVER,1,POISONGAS,1,DEFENSECURL,5,EMBER,9,SMOG,12,HAZE,16,INCINERATE,19,CLEARSMOG,22,GYROBALL,26,CORRODE,30,SUNNYDAY,36,LAVAPLUME,40,DESTINYBOND,44,CORROSIVEGAS,49,ACIDRAIN,53,MEMENTO,57,ERUPTION,TutorMoves = TOXIC,HIDDENPOWER,SUNNYDAY,PROTECT,FRUSTRATION,RETURN,REFLECT,SLUDGEWAVE,FLAMETHROWER,SLUDGEBOMB,FIREBLAST,FACADE,REST,ATTRACT,OVERHEAT,SCALD,INCINERATE,WILLOWISP,EXPLOSION,SUBSTITUTE,HEATWAVE,SLEEPTALK,WEATHERBALL,FIRESPIN,CHARGEBEAM,SOLARBEAM,SOLARBLADE,MUDSHACKLES,STEALTHROCK,BEATUP,ALLERGY,ACIDRAIN,GASTROACID,ACIDARMOR,HEX,CURSE,CONFUSERAY,OMINOUSWIND,METEORDRIVE,GAMMARAY,GRAVITY,ROUND,ECHOEDVOICE,SCHIZOPHRENIA,RAYOFLIGHT,SIGNALBEAM,BODYSLAM,BALANCERCHANGEREQUIRED,NASTYPLOT,GUNKSHOT,SHADOWBALL,GYROBALL,BEJEWELED,POWERGEM,BURNINGJEALOUSY,FIREPLEDGE,SHOCKWAVE,SCORCHINGSANDS,STEAMROLLER,ZENHEADBUTT,TWINBEAM,WORKUP,CORROSIVEGAS,VITALITYDRAIN,MEMENTO,GRUDGE,BODYPRESS,TIMEBOMB,DEFOG,WAIL,COUPDEGRACE,ANCIENTPOWER,GLISTEN,HYPERBEAM,GIGAIMPACT,TOXICSPIKES,EggGroups = Amorphous,HatchSteps = 5355,Height = 1.2,Weight = 9.5,Color = Red,Shape = Head,Category = Volcanic Gas,Pokedex = The superheated atmosphere of a volcano makes their chemical composition far more unstable and likely to attract more gaseous tumours on its body.,Generation = 1,#-------------------------------,[SOLOSIS]
B4: [SOLOSIS],Name = Solosis,Types = WATER,PSYCHIC,BaseStats = 45,20,60,20,85,60,GenderRatio = Female50Percent,GrowthRate = Parabolic,BaseExp = 58,EVs = SPECIAL_ATTACK,1,CatchRate = 200,Happiness = 70,Abilities = TORRENT,MAGICBOUNCE,HiddenAbilities = TECHNICIAN,Moves = 1,BUBBLE,1,WATERSPORT,5,CONFUSION,10,HEALBLOCK,14,ICYWIND,18,WATERPULSE,22,SOAK,25,PSYSHOCK,29,REFLECT,29,LIGHTSCREEN,34,RECOVER,38,FREEZEDRY,41,SCALD,45,PSYCHIC,48,TRICKROOM,52,HYDROPUMP,56,CHECKMATE,TutorMoves = PSYSHOCK,CALMMIND,TOXIC,HAIL,HIDDENPOWER,ICEBEAM,LIGHTSCREEN,PROTECT,RAINDANCE,SAFEGUARD,FRUSTRATION,RETURN,PSYCHIC,SHADOWBALL,REFLECT,FACADE,REST,ATTRACT,SCALD,GYROBALL,SUBSTITUTE,TRICKROOM,LIQUIDATION,COSMICPOWER,ICYWIND,MAGICROOM,SLEEPTALK,WATERPULSE,WONDERROOM,ZENHEADBUTT,TIDALWAVE,SUBMERGE,WEATHERBALL,ICICLESPEAR,BOUNCE,GRASSKNOT,MINDDRAIN,ARCANEENERGY,FAKETEARS,TAUNT,CHARM,WHIRLPOOL,BRINE,HYDROPUMP,SOAK,ACIDARMOR,HEX,CURSE,CONFUSERAY,SWIFT,WISH,GRAVITY,STARDUSTREVERIE,SIGNALBEAM,BODYSLAM,TRIATTACK,LIQUIDNITROGEN,BLOODRITUAL,NASTYPLOT,MYSTICPULSE,FAESBLESSING,BLACKHOLE,HYPOTHERMIA,EXPANDINGFORCE,TERRAINPULSE,TWINBEAM,WORKUP,WATERPLEDGE,WAIL,EggMoves = ACIDARMOR,GUARDSWAP,POWERSWAP,SPEEDSWAP,TRICK,STOREDPOWER,BUBBLEBEAM,HYPNOSIS,KARMASPELL,EggGroups = Amorphous,HatchSteps = 5355,Height = 0.3,Weight = 1.0,Color = Blue,Shape = Head,Category = Sea Amoeba,Pokedex = They do not like light and are found in dark waters. They use their remote psychic ability to find food to sustain itself.,Generation = 5,Evolutions = DUOSION,Level,27
B5: [DUOSION],Name = Duosion,Types = WATER,PSYCHIC,BaseStats = 60,35,70,35,100,70,GenderRatio = Female50Percent,GrowthRate = Parabolic,BaseExp = 130,EVs = SPECIAL_ATTACK,2,CatchRate = 100,Happiness = 70,Abilities = TORRENT,MAGICBOUNCE,HiddenAbilities = TECHNICIAN,Moves = 1,BUBBLE,1,WATERSPORT,5,CONFUSION,10,HEALBLOCK,14,ICYWIND,18,WATERPULSE,22,SOAK,25,PSYSHOCK,29,REFLECT,29,LIGHTSCREEN,34,RECOVER,38,FREEZEDRY,41,SCALD,45,PSYCHIC,48,TRICKROOM,52,HYDROPUMP,56,CHECKMATE,TutorMoves = PSYSHOCK,CALMMIND,TOXIC,HAIL,HIDDENPOWER,ICEBEAM,LIGHTSCREEN,PROTECT,RAINDANCE,SAFEGUARD,FRUSTRATION,RETURN,PSYCHIC,SHADOWBALL,REFLECT,FACADE,REST,ATTRACT,SCALD,GYROBALL,SUBSTITUTE,TRICKROOM,LIQUIDATION,COSMICPOWER,ICYWIND,MAGICROOM,SLEEPTALK,WATERPULSE,WONDERROOM,ZENHEADBUTT,TIDALWAVE,SUBMERGE,WEATHERBALL,ICICLESPEAR,BOUNCE,GRASSKNOT,MINDDRAIN,ARCANEENERGY,FAKETEARS,TAUNT,CHARM,WHIRLPOOL,BRINE,HYDROPUMP,SOAK,ACIDARMOR,HEX,CURSE,CONFUSERAY,SWIFT,WISH,GRAVITY,STARDUSTREVERIE,SIGNALBEAM,BODYSLAM,TRIATTACK,LIQUIDNITROGEN,BLOODRITUAL,NASTYPLOT,MYSTICPULSE,FAESBLESSING,BLACKHOLE,HYPOTHERMIA,EXPANDINGFORCE,TERRAINPULSE,TWINBEAM,WORKUP,WATERPLEDGE,WAIL,AURASPHERE,EggGroups = Amorphous,HatchSteps = 5355,Height = 0.6,Weight = 8.0,Color = Blue,Shape = Head,Category = Mitochondria,Pokedex = It exhibited significant psychic potential when it was just a single-celled organism. Imagine the power it now possesses now that it has evolved.,Generation = 5,Evolutions = REUNICLUS,Level,44,#-------------------------------
B6: [REUNICLUS],Name = Reuniclus,Types = WATER,PSYCHIC,BaseStats = 70,45,95,55,130,95,GenderRatio = Female50Percent,GrowthRate = Parabolic,BaseExp = 221,EVs = SPECIAL_ATTACK,3,CatchRate = 100,Happiness = 70,Abilities = TORRENT,MAGICBOUNCE,HiddenAbilities = TECHNICIAN,Moves = 0,CALMMIND,1,CALMMIND,1,BUBBLE,1,WATERSPORT,5,CONFUSION,10,HEALBLOCK,14,ICYWIND,18,WATERPULSE,22,SOAK,25,PSYSHOCK,29,REFLECT,29,LIGHTSCREEN,34,RECOVER,38,FREEZEDRY,41,SCALD,45,PSYCHIC,48,TRICKROOM,52,HYDROPUMP,56,CHECKMATE,TutorMoves = PSYSHOCK,CALMMIND,TOXIC,HAIL,HIDDENPOWER,ICEBEAM,LIGHTSCREEN,PROTECT,RAINDANCE,SAFEGUARD,FRUSTRATION,RETURN,PSYCHIC,SHADOWBALL,REFLECT,FACADE,REST,ATTRACT,SCALD,GYROBALL,SUBSTITUTE,TRICKROOM,LIQUIDATION,COSMICPOWER,ICYWIND,MAGICROOM,SLEEPTALK,WATERPULSE,WONDERROOM,ZENHEADBUTT,TIDALWAVE,SUBMERGE,WEATHERBALL,ICICLESPEAR,BOUNCE,GRASSKNOT,MINDDRAIN,ARCANEENERGY,FAKETEARS,TAUNT,CHARM,WHIRLPOOL,BRINE,HYDROPUMP,SOAK,ACIDARMOR,HEX,CURSE,CONFUSERAY,SWIFT,WISH,GRAVITY,STARDUSTREVERIE,SIGNALBEAM,BODYSLAM,TRIATTACK,LIQUIDNITROGEN,BLOODRITUAL,NASTYPLOT,MYSTICPULSE,FAESBLESSING,BLACKHOLE,HYPOTHERMIA,EXPANDINGFORCE,TERRAINPULSE,TWINBEAM,WORKUP,WATERPLEDGE,WAIL,FOCUSBLAST,GIGAIMPACT,BLIZZARD,HYPERBEAM,AURASPHERE,EggGroups = Amorphous,HatchSteps = 5355,Height = 1.0,Weight = 20.1,Color = Blue,Shape = HeadArms,Category = Water Bender,Pokedex = These Pokemon are capable of bending water to its will and forming fantastic water sculptures with its mind.,Generation = 5,#-------------------------------,[GASTLY]
B7: [GASTLY],Name = Gastly,Types = ICE,FLYING,BaseStats = 30,30,30,85,100,35,GenderRatio = Female50Percent,GrowthRate = Parabolic,BaseExp = 62,EVs = SPECIAL_ATTACK,1,CatchRate = 190,Happiness = 70,Abilities = FILTER,CLOUDNINE,HiddenAbilities = SNOWWARNING,Moves = 1,POWDERSNOW,5,GUST,9,HAIL,14,ICYWIND,20,TURBULENCE,26,FROSTBREATH,31,DEFOG,36,EROSION,41,AIRSLASH,45,ICEBEAM,49,STARDUSTREVERIE,53,TAILWIND,58,BOREASBREATH,62,BLIZZARD,TutorMoves = TOXIC,HAIL,HIDDENPOWER,ICEBEAM,BLIZZARD,LIGHTSCREEN,PROTECT,RAINDANCE,SAFEGUARD,FRUSTRATION,THUNDERBOLT,RETURN,REFLECT,FACADE,REST,ATTRACT,SUBSTITUTE,AURORAVEIL,HURRICANE,DEFOG,ICYWIND,OMINOUSWIND,SLEEPTALK,TAILWIND,ICICLECRASH,WEATHERBALL,ICYWIND,ICICLESPEAR,AVALANCHE,FROZENHEART,CHARGEBEAM,EERIEIMPULSE,FLY,AIRSLASH,TURBULENCE,DEATHVORTEX,TRICK,WONDERROOM,MAGICROOM,MINDDRAIN,TAUNT,SOAK,ACIDRAIN,HEX,CURSE,CONFUSERAY,MEANLOOK,COSMICPOWER,GRAVITY,STARDUSTREVERIE,SCHIZOPHRENIA,RAYOFLIGHT,TRIATTACK,LIQUIDNITROGEN,CALMMIND,BLOODRITUAL,NASTYPLOT,GYROBALL,BOREASBREATH,HURRICANE,TORNADO,ICECOMET,HYPOTHERMIA,SHOCKWAVE,WORKUP,WATERPULSE,WATERPLEDGE,EggMoves = AURORAVEIL,HURRICANE,RAINDANCE,TRIATTACK,FROZENHEART,LIQUIDNITROGEN,ICEVORTEX,CHECKMATE,TORNADO,FREEZEDRY,EggGroups = Amorphous,HatchSteps = 5355,Height = 1.3,Weight = 0.1,Color = Blue,Shape = Head,Category = Mist,Pokedex = Whenever hail falls, you can likely credit a Gastly as being responsible for starting it.,Generation = 1,Evolutions = HAUNTER,Level,25
B8: [HAUNTER],Name = Haunter,Types = ICE,FLYING,BaseStats = 50,45,45,95,115,55,GenderRatio = Female50Percent,GrowthRate = Parabolic,BaseExp = 142,EVs = SPECIAL_ATTACK,2,CatchRate = 100,Happiness = 70,Abilities = FILTER,CLOUDNINE,HiddenAbilities = SNOWWARNING,Moves = 0,WEATHERBALL,1,WEATHERBALL,1,POWDERSNOW,5,GUST,9,HAIL,14,ICYWIND,20,TURBULENCE,26,FROSTBREATH,31,DEFOG,36,EROSION,41,AIRSLASH,45,ICEBEAM,49,STARDUSTREVERIE,53,TAILWIND,58,BOREASBREATH,62,BLIZZARD,TutorMoves = TOXIC,HAIL,HIDDENPOWER,ICEBEAM,BLIZZARD,LIGHTSCREEN,PROTECT,RAINDANCE,SAFEGUARD,FRUSTRATION,THUNDERBOLT,RETURN,REFLECT,FACADE,REST,ATTRACT,SUBSTITUTE,AURORAVEIL,HURRICANE,DEFOG,ICYWIND,OMINOUSWIND,SLEEPTALK,TAILWIND,ICICLECRASH,WEATHERBALL,ICYWIND,ICICLESPEAR,AVALANCHE,FROZENHEART,CHARGEBEAM,EERIEIMPULSE,FLY,AIRSLASH,TURBULENCE,DEATHVORTEX,TRICK,WONDERROOM,MAGICROOM,MINDDRAIN,TAUNT,SOAK,ACIDRAIN,HEX,CURSE,CONFUSERAY,MEANLOOK,COSMICPOWER,GRAVITY,STARDUSTREVERIE,SCHIZOPHRENIA,RAYOFLIGHT,TRIATTACK,LIQUIDNITROGEN,CALMMIND,BLOODRITUAL,NASTYPLOT,GYROBALL,BOREASBREATH,HURRICANE,TORNADO,ICECOMET,HYPOTHERMIA,SHOCKWAVE,WORKUP,WATERPULSE,WATERPLEDGE,THUNDER,ICEPUNCH,MEMENTO,EggGroups = Amorphous,HatchSteps = 5355,Height = 1.6,Weight = 0.1,Color = Blue,Shape = HeadArms,Category = Freezing Rain,Pokedex = Haunters are mischievous creatures. Their command of ice allows them to set up icy traps for unsuspecting passerbys.,Generation = 1,Evolutions = GENGAR,Item,WINDSTONE,#-------------------------------
B9: [GENGAR],Name = Gengar,Types = ICE,FLYING,BaseStats = 65,60,60,115,130,70,GenderRatio = Female50Percent,GrowthRate = Parabolic,BaseExp = 225,EVs = SPECIAL_ATTACK,3,CatchRate = 100,Happiness = 70,Abilities = FILTER,CLOUDNINE,HiddenAbilities = SNOWWARNING,Moves = 0,MEMENTO,1,MEMENTO,1,WEATHERBALL,1,POWDERSNOW,5,GUST,9,HAIL,14,ICYWIND,20,TURBULENCE,26,FROSTBREATH,31,DEFOG,36,EROSION,41,AIRSLASH,45,ICEBEAM,49,STARDUSTREVERIE,53,TAILWIND,58,BOREASBREATH,62,BLIZZARD,TutorMoves = TOXIC,HAIL,HIDDENPOWER,ICEBEAM,BLIZZARD,LIGHTSCREEN,PROTECT,RAINDANCE,SAFEGUARD,FRUSTRATION,THUNDERBOLT,RETURN,REFLECT,FACADE,REST,ATTRACT,SUBSTITUTE,AURORAVEIL,HURRICANE,DEFOG,ICYWIND,OMINOUSWIND,SLEEPTALK,TAILWIND,ICICLECRASH,WEATHERBALL,ICYWIND,ICICLESPEAR,AVALANCHE,FROZENHEART,CHARGEBEAM,EERIEIMPULSE,FLY,AIRSLASH,TURBULENCE,DEATHVORTEX,TRICK,WONDERROOM,MAGICROOM,MINDDRAIN,TAUNT,SOAK,ACIDRAIN,HEX,CURSE,CONFUSERAY,MEANLOOK,COSMICPOWER,GRAVITY,STARDUSTREVERIE,SCHIZOPHRENIA,RAYOFLIGHT,TRIATTACK,LIQUIDNITROGEN,CALMMIND,BLOODRITUAL,NASTYPLOT,GYROBALL,BOREASBREATH,HURRICANE,TORNADO,ICECOMET,HYPOTHERMIA,SHOCKWAVE,WORKUP,WATERPULSE,WATERPLEDGE,THUNDER,ICEPUNCH,MEMENTO,EggGroups = Amorphous,HatchSteps = 5355,Height = 1.5,Weight = 40.5,Color = Blue,Shape = BipedalTail,Category = Nimbus,Pokedex = Due to its mastery of cloud systems, Gengars are capable of summoning powerful hailstorms and blizzards at will.,#-------------------------------,[DODUO],Name = Doduo
B10: [DODUO],Name = Doduo,Types = COSMIC,FLYING,BaseStats = 45,35,35,75,75,45,GenderRatio = Female50Percent,GrowthRate = Medium,BaseExp = 62,EVs = SPEED,1,CatchRate = 190,Happiness = 70,Abilities = EARLYBIRD,COMPETITIVE,HiddenAbilities = NAIVETY,Moves = 1,GUST,1,STARDUST,5,SWIFT,10,CONFUSION,14,BLACKOUT,19,TWINSTARS,23,TURBULENCE,28,HYPNOSIS,32,COSMICPOWER,37,AIRSLASH,40,PSYCHIC,44,MOONLIGHT,48,MOONBLAST,52,BOREASBREATH,56,METEORBEAM,TutorMoves = PSYSHOCK,CALMMIND,TOXIC,HIDDENPOWER,LIGHTSCREEN,PROTECT,RAINDANCE,SAFEGUARD,FRUSTRATION,RETURN,PSYCHIC,SHADOWBALL,REFLECT,FACADE,REST,ATTRACT,THIEF,ROUND,ECHOEDVOICE,STEELWING,UTURN,SUBSTITUTE,TRICKROOM,WORKUP,COSMICPOWER,BRAVEBIRD,HELPINGHAND,HYPERVOICE,KNOCKOFF,ROOST,WONDERROOM,MOONBLAST,SUNNYDAY,ICYWIND,HAIL,EERIEIMPULSE,CHARGEBEAM,FLY,BOUNCE,AIRSLASH,FEATHERDANCE,TURBULENCE,DEATHVORTEX,UTURN,FLUTTER,TRICKROOM,MAGICROOM,WONDERROOM,PSYCHICTERRAIN,TAUNT,SIRENSSONG,RAINDANCE,LOWSWEEP,LOWKICK,CURSE,CONFUSERAY,SWIFT,WISH,METEORDRIVE,GAMMARAY,GRAVITY,STARDUSTREVERIE,LULLABY,SIGNALBEAM,TRIPLEKICK,PSYCHIC,BLOODRITUAL,DARKPULSE,SHADOWBALL,NASTYPLOT,SWORDSDANCE,BOREASBREATH,HURRICANE,TORNADO,AURASPHERE,BLACKHOLE,HYPOTHERMIA,SHOCKWAVE,EXPANDINGFORCE,TERRAINPULSE,FOULPLAY,EggMoves = FEATHERDANCE,REFLECT,LIGHTSCREEN,STOREDPOWER,BRAVEBIRD,TAILWIND,WISH,EggGroups = Flying,HatchSteps = 5355,Height = 1.4,Weight = 39.2,Color = Blue,Shape = HeadLegs,Category = Galaxy,Pokedex = It can channel the power of the night sky into its attacks. It forgoes physical violence in favour of attacking from afar with its nascent mind.,Generation = 1,Evolutions = DODRIO,Item,MOONSTONE
B11: [DODRIO],Name = Dodrio,Types = COSMIC,FLYING,BaseStats = 70,60,60,105,100,75,GenderRatio = Female50Percent,GrowthRate = Medium,BaseExp = 161,EVs = SPEED,2,CatchRate = 100,Happiness = 70,Abilities = EARLYBIRD,COMPETITIVE,HiddenAbilities = NAIVETY,Moves = 0,STARSALIGNED,1,STARSALIGNED,1,TRIATTACK,1,GUST,1,STARDUST,5,SWIFT,10,CONFUSION,14,BLACKOUT,19,TWINSTARS,23,TURBULENCE,28,HYPNOSIS,32,COSMICPOWER,37,AIRSLASH,40,PSYCHIC,44,MOONLIGHT,48,MOONBLAST,52,BOREASBREATH,56,METEORBEAM,TutorMoves = PSYSHOCK,CALMMIND,TOXIC,HIDDENPOWER,LIGHTSCREEN,PROTECT,RAINDANCE,SAFEGUARD,FRUSTRATION,RETURN,PSYCHIC,SHADOWBALL,REFLECT,FACADE,REST,ATTRACT,THIEF,ROUND,ECHOEDVOICE,STEELWING,UTURN,SUBSTITUTE,TRICKROOM,WORKUP,COSMICPOWER,BRAVEBIRD,HELPINGHAND,HYPERVOICE,KNOCKOFF,ROOST,WONDERROOM,MOONBLAST,SUNNYDAY,ICYWIND,HAIL,EERIEIMPULSE,CHARGEBEAM,FLY,BOUNCE,AIRSLASH,FEATHERDANCE,TURBULENCE,DEATHVORTEX,UTURN,FLUTTER,TRICKROOM,MAGICROOM,WONDERROOM,PSYCHICTERRAIN,TAUNT,SIRENSSONG,RAINDANCE,LOWSWEEP,LOWKICK,CURSE,CONFUSERAY,SWIFT,WISH,METEORDRIVE,GAMMARAY,GRAVITY,STARDUSTREVERIE,LULLABY,SIGNALBEAM,TRIPLEKICK,PSYCHIC,BLOODRITUAL,DARKPULSE,SHADOWBALL,NASTYPLOT,SWORDSDANCE,BOREASBREATH,HURRICANE,TORNADO,AURASPHERE,BLACKHOLE,HYPOTHERMIA,SHOCKWAVE,EXPANDINGFORCE,TERRAINPULSE,FOULPLAY,EggGroups = Flying,HatchSteps = 5355,Height = 1.8,Weight = 85.2,Color = Blue,Shape = HeadLegs,Category = Galaxy,Pokedex = It is able to look into different universes to anticipate enemy attacks.,Generation = 1,#-------------------------------,[EKANS]
B12: [EKANS],Name = Ekans,Types = GROUND,POISON,BaseStats = 40,70,44,60,40,54,GenderRatio = Female50Percent,GrowthRate = Medium,BaseExp = 58,EVs = ATTACK,1,CatchRate = 255,Happiness = 70,Abilities = CORROSION,QUICKKILL,HiddenAbilities = BLOODTHIRST,Moves = 1,WRAP,1,LEER,5,POISONSTING,8,MEGAPHONE,12,SANDTOMB,16,BITE,20,POISONFANG,24,DIG,28,BATTLECRY,33,CRUNCH,37,TOXIC,41,COIL,44,POISONJAB,48,VENDETTA,52,CONTINENTALRIFT,56,GUNKSHOT,TutorMoves = TOXIC,ALLERGY,HIDDENPOWER,PROTECT,FRUSTRATION,RETURN,DIG,SLUDGEWAVE,SLUDGEBOMB,SANDSTORM,FACADE,REST,ATTRACT,THIEF,SCORESETTLER,BULLDOZE,POISONJAB,SUBSTITUTE,WORKUP,VENOMDRENCH,CRUNCH,FOULPLAY,GASTROACID,GUNKSHOT,SLEEPTALK,LEECHLIFE,SUNNYDAY,FIREFANG,ICEFANG,THUNDERFANG,PINMISSILE,UTURN,SANDTOMB,MUDSHACKLES,QUICKSAND,SPIKES,MUDSLIDE,GAIAPULSE,MINDDRAIN,ROCKSLIDE,ROCKTOMB,ROCKBLAST,STEALTHROCK,MINERALWAVE,ASSURANCE,SNARL,BRUTALSWING,TAUNT,VENDETTA,LOWSWEEP,CROSSPOISON,TOXICSPIKES,POISONFANG,ACIDARMOR,BREAKINGSWIPE,ANCIENTGLARE,CURSE,CONFUSERAY,MEANLOOK,EARTHPOWER,BLOODRITUAL,PSYCHICFANGS,OUTRAGE,DRAGONDANCE,THROATCHOP,SWORDSDANCE,BOOMBOX,CATAPULT,SCORCHINGSANDS,SPOIL,CORROSIVEGAS,SCALESHOT,DRAGONBREATH,ENDERSHOCK,LASHOUT,VITALITYDRAIN,GRUDGE,COUPDEGRACE,EXTREMESPEED,ANCIENTPOWER,EggMoves = SWORDSDANCE,DRAGONTAIL,NAGASKIN,KNOCKOFF,CLANGINGSCALES,QUICKSAND,BALANCERCHANGEREQUIRED,SCREECH,EggGroups = Field,Dragon,HatchSteps = 5355,Height = 2.0,Weight = 6.9,Color = Brown,Shape = Serpentine,Category = Rattlesnake,Pokedex = The rhythmic sound of an Ekans's tail is enough to put its foe to sleep when it can then move in to consume it whole.,Generation = 1,Evolutions = ARBOK,Level,30
B13: [ARBOK],Name = Arbok,Types = GROUND,POISON,BaseStats = 55,110,69,100,65,69,GenderRatio = Female50Percent,GrowthRate = Medium,BaseExp = 153,EVs = ATTACK,2,CatchRate = 100,Happiness = 70,Abilities = CORROSION,QUICKKILL,HiddenAbilities = BLOODTHIRST,Moves = 0,GLARE,1,GLARE,1,WRAP,1,LEER,5,POISONSTING,8,QUICKSAND,12,SANDTOMB,16,BITE,20,POISONFANG,24,DIG,31,BATTLECRY,35,CRUNCH,40,TOXIC,44,COIL,48,POISONJAB,52,VENDETTA,56,CONTINENTALRIFT,60,GUNKSHOT,TutorMoves = TOXIC,ALLERGY,HIDDENPOWER,PROTECT,FRUSTRATION,RETURN,DIG,SLUDGEWAVE,SLUDGEBOMB,SANDSTORM,FACADE,REST,ATTRACT,THIEF,SCORESETTLER,BULLDOZE,POISONJAB,SUBSTITUTE,WORKUP,VENOMDRENCH,CRUNCH,FOULPLAY,GASTROACID,GUNKSHOT,SLEEPTALK,LEECHLIFE,SUNNYDAY,FIREFANG,ICEFANG,THUNDERFANG,PINMISSILE,UTURN,SANDTOMB,MUDSHACKLES,QUICKSAND,SPIKES,MUDSLIDE,GAIAPULSE,MINDDRAIN,ROCKSLIDE,ROCKTOMB,ROCKBLAST,STEALTHROCK,MINERALWAVE,ASSURANCE,SNARL,BRUTALSWING,TAUNT,VENDETTA,LOWSWEEP,CROSSPOISON,TOXICSPIKES,POISONFANG,ACIDARMOR,BREAKINGSWIPE,ANCIENTGLARE,CURSE,CONFUSERAY,MEANLOOK,EARTHPOWER,BLOODRITUAL,PSYCHICFANGS,OUTRAGE,DRAGONDANCE,THROATCHOP,SWORDSDANCE,BOOMBOX,CATAPULT,SCORCHINGSANDS,SPOIL,CORROSIVEGAS,SCALESHOT,DRAGONBREATH,ENDERSHOCK,LASHOUT,VITALITYDRAIN,GRUDGE,COUPDEGRACE,EXTREMESPEED,ANCIENTPOWER,HYPERBEAM,GIGAIMPACT,EARTHQUAKE,EggGroups = Field,Dragon,HatchSteps = 5355,Height = 3.5,Weight = 65.0,Color = Brown,Shape = Serpentine,Category = Rattlesnake,Pokedex = The poison of an Arbok is so corrosive that it can melt steel beams. It is able to manipulate the face on its body into different shapes to fool its prey.,Generation = 1,#-------------------------------,[STARYU]
... B698: [CARNIVINE],Name = Carnivine,Types = GRASS,BUG,BaseStats = 74,100,72,46,90,72,GenderRatio = Female50Percent,GrowthRate = Slow,BaseExp = 159,EVs = ATTACK,2,CatchRate = 200,Happiness = 70,Abilities = LEVITATE,Moves = 1,BIND,1,GROWTH,7,BITE,11,VINEWHIP,17,SWEETSCENT,21,INGRAIN,27,FEINTATTACK,31,FORESTLEAP,37,STOCKPILE,37,SPITUP,37,SWALLOW,41,CRUNCH,47,WRINGOUT,50,POWERWHIP,TutorMoves = ATTRACT,BIND,BUGBITE,BULLETSEED,CONFIDE,CUT,DEFOG,DOUBLETEAM,ENDURE,ENERGYBALL,FACADE,FLING,FRUSTRATION,GASTROACID,GIGADRAIN,GIGAIMPACT,GRASSKNOT,HIDDENPOWER,HYPERBEAM,INFESTATION,KNOCKOFF,NATUREPOWER,SCORESETTLER,PROTECT,REST,RETURN,ROUND,PEPPERBURST,SLEEPTALK,SLUDGEBOMB,SNORE,SOLARBEAM,SUBSTITUTE,SUNNYDAY,SWAGGER,SWORDSDANCE,SYNTHESIS,THIEF,THROATCHOP,TOXIC,WORRYSEED,EggMoves = SLEEPPOWDER,STUNSPORE,RAZORLEAF,SLAM,SYNTHESIS,MAGICALLEAF,LEECHSEED,WORRYSEED,GIGADRAIN,RAGEPOWDER,GRASSWHISTLE,VILEFUMES,EggGroups = Grass,HatchSteps = 6400,Height = 1.4,Weight = 27.0,Color = Green,Shape = Multiped,Category = Fly Trap,Pokedex = It binds itself to trees in marshes. It attracts prey with its sweet-smelling drool and gulps them down.,Generation = 4,,

Sheet Worksheet Forms
A1: [SHELLOS,1] | E1: =A1&","&A2&","&A3&","&A4&","&A5&","&A6&","&A7&","&A8&","&A9 -> [SHELLOS,1],FormName = Shellnite,Types = DRAGON,WATER,BaseStats = 64,40,40,57,75,59,EVs = SPECIAL_ATTACK,1,Abilities = GOOEY,SWIFTSWIM,HiddenAbilities = DRIZZLE,Moves = 1,WATERGUN,1,TWISTER,5,MIMIC,9,THUNDERWAVE,13,AQUARING,16,DRAGONBREATH,20,SOAK,24,BRINE,28,GLARE,33,DRAGONGALE,36,MUDDYWATER,40,HURRICANE,44,RAINDANCE,49,DRACOMETEOR,EggMoves = AURORABEAM,OCTAZOOKA,WATERPULSE,AQUAJET,MIST,YAWN,AMNESIA
A2: FormName = Shellnite
A3: Types = DRAGON,WATER
A4: BaseStats = 64,40,40,57,75,59
A5: EVs = SPECIAL_ATTACK,1
A6: Abilities = GOOEY,SWIFTSWIM
A7: HiddenAbilities = DRIZZLE
A8: Moves = 1,WATERGUN,1,TWISTER,5,MIMIC,9,THUNDERWAVE,13,AQUARING,16,DRAGONBREATH,20,SOAK,24,BRINE,28,GLARE,33,DRAGONGALE,36,MUDDYWATER,40,HURRICANE,44,RAINDANCE,49,DRACOMETEOR
A9: EggMoves = AURORABEAM,OCTAZOOKA,WATERPULSE,AQUAJET,MIST,YAWN,AMNESIA
A10: #-------------------------------
A11: [GASTRODON,1] | E11: =A11&","&A12&","&A13&","&A14&","&A15&","&A16&","&A17&","&A18&","&A19 -> [GASTRODON,1],FormName = Gastronair,Types = DRAGON,WATER,BaseStats = 95,50,57,85,110,88,EVs = SPECIAL_ATTACK,2,Abilities = GOOEY,SWIFTSWIM,HiddenAbilities = DRIZZLE,Moves = 0,LIFEDEW,1,LIFEDEW,1,WATERGUN,1,TWISTER,5,MIMIC,9,THUNDERWAVE,13,AQUARING,16,DRAGONBREATH,20,SOAK,24,BRINE,28,GLARE,33,DRAGONGALE,36,MUDDYWATER,40,HURRICANE,44,RAINDANCE,49,DRACOMETEOR,#-------------------------------
A12: FormName = Gastronair
A13: Types = DRAGON,WATER
A14: BaseStats = 95,50,57,85,110,88
A15: EVs = SPECIAL_ATTACK,2
A16: Abilities = GOOEY,SWIFTSWIM
A17: HiddenAbilities = DRIZZLE
A18: Moves = 0,LIFEDEW,1,LIFEDEW,1,WATERGUN,1,TWISTER,5,MIMIC,9,THUNDERWAVE,13,AQUARING,16,DRAGONBREATH,20,SOAK,24,BRINE,28,GLARE,33,DRAGONGALE,36,MUDDYWATER,40,HURRICANE,44,RAINDANCE,49,DRACOMETEOR
A19: #-------------------------------
A20: [SHELLOS,2] | E20: =A20&","&A21&","&A22&","&A23&","&A24&","&A25&","&A26&","&A27&","&A28 -> [SHELLOS,2],FormName = Shew,Types = DRAGON,STEEL,BaseStats = 65,70,80,45,44,47,EVs = DEFENSE,1,Abilities = GOOEY,FORTIFICATION,HiddenAbilities = SHEERFORCE,Moves = 1,SNAPTRAP,1,DRAGONFURY,5,MIMIC,9,SHARPEN,13,DRAGONMAGIC,16,DRAGONGNAW,20,FALSESWIPE,24,VISEGRIP,28,GLARE,33,DRACOSHRED,36,SHIELDBASH,40,CRUNCH,44,KINGSSHIELD,49,DRACONICCRASH,TutorMoves = ANCIENTGLARE,ATTRACT,AURASPHERE,BEJEWELED,BODYPRESS,BREAKINGSWIPE,BULKUP,BULLDOZE,BULLETSEED,BURNINGJEALOUSY,CHIDORI,CLOSECOMBAT,COACHING,CONFUSERAY,COUPDEGRACE,CRUNCH,CURSE,DARKPULSE,DAZZLINGGLEAM,DEADLYREACH,DIVINEPUNISHMENT,DRACARYS,DRACOMETEOR,DRAGONBLOOD,DRAGONBREATH,DRAGONDANCE,DRAGONMAGIC,DRAININGKISS,DRAINPUNCH,DUALWINGBEAT,EARTHPOWER,EARTHQUAKE,ECHOEDVOICE,FABLEDRUSH,FALSESWIPE,FEATHERDANCE,FLIPTURN,FIREFANG,FLAMETHROWER,FLAREBLITZ,FOCUSBLAST,FORTISSIMO,FURYCUTTER,GASTROACID,GOLDENBULLET,GOLDRUSH,GYROBALL,HEATWAVE,HEX,HIDDENPOWER,HIVEMIND,HYPERVOICE,ICEFANG,INCINERATE,IRONDEFENSE,IRONHEAD,KNOCKOFF,LASHOUT,LEECHLIFE,MAGNETICCANNON,MEMENTO,METEORBEAM,METEORDRIVE,METEORMASH,MINERALWAVE,MUDSHACKLES,MUDSLIDE,NASTYPLOT,NOBLEROAR,OUTRAGE,PLAYROUGH,POISONFANG,POISONJAB,POWERUPPUNCH,PROTECT,REST,RETURN,ROCKBLAST,ROCKSLIDE,ROCKTOMB,SANDTOMB,SANDSTORM,SCALD,SCALESHOT,SCORCHINGSANDS,SHADOWBALL,SLEEPTALK,SLUDGEBOMB,SLUDGEWAVE,SNARL,SOAK,SOLARBEAM,SOLARECLIPSE,SPIKES,STARDUSTREVERIE,STEALTHROCK,STEELROLLER,STONEEDGE,SUBSTITUTE,SUPERPOWER,SWORDSDANCE,TAUNT,TERRAINPULSE,THUNDERFANG,THUNDERPUNCH,THUNDERWAVE,TOXIC,TOXICSPIKES,TRIATTACK,UTURN,VENDETTA,VITALITYDRAIN,WILDCHARGE,WORKUP,ZENHEADBUTT
A21: FormName = Shew
A22: Types = DRAGON,STEEL
A23: BaseStats = 65,70,80,45,44,47
A24: EVs = DEFENSE,1
A25: Abilities = GOOEY,FORTIFICATION
A26: HiddenAbilities = SHEERFORCE
A27: Moves = 1,SNAPTRAP,1,DRAGONFURY,5,MIMIC,9,SHARPEN,13,DRAGONMAGIC,16,DRAGONGNAW,20,FALSESWIPE,24,VISEGRIP,28,GLARE,33,DRACOSHRED,36,SHIELDBASH,40,CRUNCH,44,KINGSSHIELD,49,DRACONICCRASH
A28: TutorMoves = ANCIENTGLARE,ATTRACT,AURASPHERE,BEJEWELED,BODYPRESS,BREAKINGSWIPE,BULKUP,BULLDOZE,BULLETSEED,BURNINGJEALOUSY,CHIDORI,CLOSECOMBAT,COACHING,CONFUSERAY,COUPDEGRACE,CRUNCH,CURSE,DARKPULSE,DAZZLINGGLEAM,DEADLYREACH,DIVINEPUNISHMENT,DRACARYS,DRACOMETEOR,DRAGONBLOOD,DRAGONBREATH,DRAGONDANCE,DRAGONMAGIC,DRAININGKISS,DRAINPUNCH,DUALWINGBEAT,EARTHPOWER,EARTHQUAKE,ECHOEDVOICE,FABLEDRUSH,FALSESWIPE,FEATHERDANCE,FLIPTURN,FIREFANG,FLAMETHROWER,FLAREBLITZ,FOCUSBLAST,FORTISSIMO,FURYCUTTER,GASTROACID,GOLDENBULLET,GOLDRUSH,GYROBALL,HEATWAVE,HEX,HIDDENPOWER,HIVEMIND,HYPERVOICE,ICEFANG,INCINERATE,IRONDEFENSE,IRONHEAD,KNOCKOFF,LASHOUT,LEECHLIFE,MAGNETICCANNON,MEMENTO,METEORBEAM,METEORDRIVE,METEORMASH,MINERALWAVE,MUDSHACKLES,MUDSLIDE,NASTYPLOT,NOBLEROAR,OUTRAGE,PLAYROUGH,POISONFANG,POISONJAB,POWERUPPUNCH,PROTECT,REST,RETURN,ROCKBLAST,ROCKSLIDE,ROCKTOMB,SANDTOMB,SANDSTORM,SCALD,SCALESHOT,SCORCHINGSANDS,SHADOWBALL,SLEEPTALK,SLUDGEBOMB,SLUDGEWAVE,SNARL,SOAK,SOLARBEAM,SOLARECLIPSE,SPIKES,STARDUSTREVERIE,STEALTHROCK,STEELROLLER,STONEEDGE,SUBSTITUTE,SUPERPOWER,SWORDSDANCE,TAUNT,TERRAINPULSE,THUNDERFANG,THUNDERPUNCH,THUNDERWAVE,TOXIC,TOXICSPIKES,TRIATTACK,UTURN,VENDETTA,VITALITYDRAIN,WILDCHARGE,WORKUP,ZENHEADBUTT
A29: #-------------------------------
A30: [GASTRODON,2] | E30: =A30&","&A31&","&A32&","&A33&","&A34&","&A35&","&A36&","&A37&","&A38 -> [GASTRODON,2],FormName = Gaxorus,Types = DRAGON,STEEL,BaseStats = 80,106,127,55,55,77,EVs = DEFENSE,2,Abilities = GOOEY,FORTIFICATION,HiddenAbilities = SHEERFORCE,Moves = 0,IRONDEFENSE,1,IRONDEFENSE,1,SNAPTRAP,1,DRAGONFURY,5,MIMIC,9,SHARPEN,13,DRAGONMAGIC,16,DRAGONGNAW,20,FALSESWIPE,24,VISEGRIP,28,GLARE,33,DRACOSHRED,36,SHIELDBASH,40,CRUNCH,44,KINGSSHIELD,49,DRACONICCRASH,TutorMoves = ANCIENTGLARE,ATTRACT,AURASPHERE,BEJEWELED,BODYPRESS,BREAKINGSWIPE,BULKUP,BULLDOZE,BULLETSEED,BURNINGJEALOUSY,CHIDORI,CLOSECOMBAT,COACHING,CONFUSERAY,COUPDEGRACE,CRUNCH,CURSE,DARKPULSE,DAZZLINGGLEAM,DEADLYREACH,DIVINEPUNISHMENT,DRACARYS,DRACOMETEOR,DRAGONBLOOD,DRAGONBREATH,DRAGONDANCE,DRAGONMAGIC,DRAININGKISS,DRAINPUNCH,DUALWINGBEAT,EARTHPOWER,EARTHQUAKE,ECHOEDVOICE,FABLEDRUSH,FALSESWIPE,FEATHERDANCE,FLIPTURN,FIREFANG,FLAMETHROWER,FLAREBLITZ,FOCUSBLAST,FORTISSIMO,FURYCUTTER,GASTROACID,GOLDENBULLET,GOLDRUSH,GYROBALL,HEATWAVE,HEX,HIDDENPOWER,HIVEMIND,HYPERVOICE,ICEFANG,INCINERATE,IRONDEFENSE,IRONHEAD,KNOCKOFF,LASHOUT,LEECHLIFE,MAGNETICCANNON,MEMENTO,METEORBEAM,METEORDRIVE,METEORMASH,MINERALWAVE,MUDSHACKLES,MUDSLIDE,NASTYPLOT,NOBLEROAR,OUTRAGE,PLAYROUGH,POISONFANG,POISONJAB,POWERUPPUNCH,PROTECT,REST,RETURN,ROCKBLAST,ROCKSLIDE,ROCKTOMB,SANDTOMB,SANDSTORM,SCALD,SCALESHOT,SCORCHINGSANDS,SHADOWBALL,SLEEPTALK,SLUDGEBOMB,SLUDGEWAVE,SNARL,SOAK,SOLARBEAM,SOLARECLIPSE,SPIKES,STARDUSTREVERIE,STEALTHROCK,STEELROLLER,STONEEDGE,SUBSTITUTE,SUPERPOWER,SWORDSDANCE,TAUNT,TERRAINPULSE,THUNDERFANG,THUNDERPUNCH,THUNDERWAVE,TOXIC,TOXICSPIKES,TRIATTACK,UTURN,VENDETTA,VITALITYDRAIN,WILDCHARGE,WORKUP,ZENHEADBUTT
A31: FormName = Gaxorus
A32: Types = DRAGON,STEEL
A33: BaseStats = 80,106,127,55,55,77
A34: EVs = DEFENSE,2
A35: Abilities = GOOEY,FORTIFICATION
A36: HiddenAbilities = SHEERFORCE
A37: Moves = 0,IRONDEFENSE,1,IRONDEFENSE,1,SNAPTRAP,1,DRAGONFURY,5,MIMIC,9,SHARPEN,13,DRAGONMAGIC,16,DRAGONGNAW,20,FALSESWIPE,24,VISEGRIP,28,GLARE,33,DRACOSHRED,36,SHIELDBASH,40,CRUNCH,44,KINGSSHIELD,49,DRACONICCRASH
A38: TutorMoves = ANCIENTGLARE,ATTRACT,AURASPHERE,BEJEWELED,BODYPRESS,BREAKINGSWIPE,BULKUP,BULLDOZE,BULLETSEED,BURNINGJEALOUSY,CHIDORI,CLOSECOMBAT,COACHING,CONFUSERAY,COUPDEGRACE,CRUNCH,CURSE,DARKPULSE,DAZZLINGGLEAM,DEADLYREACH,DIVINEPUNISHMENT,DRACARYS,DRACOMETEOR,DRAGONBLOOD,DRAGONBREATH,DRAGONDANCE,DRAGONMAGIC,DRAININGKISS,DRAINPUNCH,DUALWINGBEAT,EARTHPOWER,EARTHQUAKE,ECHOEDVOICE,FABLEDRUSH,FALSESWIPE,FEATHERDANCE,FLIPTURN,FIREFANG,FLAMETHROWER,FLAREBLITZ,FOCUSBLAST,FORTISSIMO,FURYCUTTER,GASTROACID,GOLDENBULLET,GOLDRUSH,GYROBALL,HEATWAVE,HEX,HIDDENPOWER,HIVEMIND,HYPERVOICE,ICEFANG,INCINERATE,IRONDEFENSE,IRONHEAD,KNOCKOFF,LASHOUT,LEECHLIFE,MAGNETICCANNON,MEMENTO,METEORBEAM,METEORDRIVE,METEORMASH,MINERALWAVE,MUDSHACKLES,MUDSLIDE,NASTYPLOT,NOBLEROAR,OUTRAGE,PLAYROUGH,POISONFANG,POISONJAB,POWERUPPUNCH,PROTECT,REST,RETURN,ROCKBLAST,ROCKSLIDE,ROCKTOMB,SANDTOMB,SANDSTORM,SCALD,SCALESHOT,SCORCHINGSANDS,SHADOWBALL,SLEEPTALK,SLUDGEBOMB,SLUDGEWAVE,SNARL,SOAK,SOLARBEAM,SOLARECLIPSE,SPIKES,STARDUSTREVERIE,STEALTHROCK,STEELROLLER,STONEEDGE,SUBSTITUTE,SUPERPOWER,SWORDSDANCE,TAUNT,TERRAINPULSE,THUNDERFANG,THUNDERPUNCH,THUNDERWAVE,TOXIC,TOXICSPIKES,TRIATTACK,UTURN,VENDETTA,VITALITYDRAIN,WILDCHARGE,WORKUP,ZENHEADBUTT
A39: #-------------------------------
A40: [SHELLOS,3] | E40: =A40&","&A41&","&A42&","&A43&","&A44&","&A45&","&A46&","&A47&","&A48 -> [SHELLOS,3],FormName = Sheino,Types = DRAGON,DARK,BaseStats = 55,65,60,74,40,43,EVs = SPEED,1,Abilities = GOOEY,HYPERCUTTER,HiddenAbilities = INTIMIDATE,Moves = 1,FAKEOUT,1,DRAGONFURY,5,MIMIC,9,PRANKCALL,13,DRAGONBLOOD,16,BREAKINGSWIPE,20,TAUNT,24,EVILTHORN,28,GLARE,33,WYVERNSLASH,36,WICKEDSTRIKE,40,CRUNCH,44,OBSTRUCT,49,DRACONICCRASH,EggMoves = BITE,PARTINGSHOT,QUASH,OUTRAGE,SNARL,ZENHEADBUTT,UPROAR
...

Sheet DIVIDER>>

Sheet Completed Species
A1: ID | B1: Internal Name | C1: Name | D1: Type1 | E1: Type2 | F1: Concatenated Types | G1: HP | H1: Attack | I1: Defense | J1: Speed | K1: Special Attack | L1: Special Defense | M1: BST Total | N1: EV_Kind1 | O1: Amount1 | P1: EV_Kind2 | Q1: Amount2 | R1: EV_Kind3 | S1: Amount3 | T1: Concatenated EVs | U1: Ability1 | V1: Ability2 | W1: HiddenAbility | X1: Concatenated Abilities | Y1: Move List | Z1: Tutor Moves | AA1: Egg Moves | AB1: Evolves into | AC1: Method | AD1: Evolve Condition | AE1: Evolves into2 | AF1: Method2 | AG1: Evolve Condition2 | AH1: Evolves into3 | AI1: Method3 | AJ1: Evolve Condition3 | AK1: Evolves into4 | AL1: Method4 | AM1: Evolve Condition4 | AN1: Evolves into5 | AO1: Method5 | AP1: Evolve Condition5 | AQ1: Evolves into6 | AR1: Method6 | AS1: Evolve Condition6 | AT1: Evolves into7 | AU1: Method7 | AV1: Evolve Condition7 | AW1: Evolves into8 | AX1: Method8 | AY1: Evolve Condition8
A2: 1 | B2: [KOFFING] | C2: Koffing | D2: ='BST Extract'!J2 -> FIRE | E2: ='BST Extract'!K2 -> POISON | F2: =D2&","&E2 -> FIRE,POISON | G2: ='BST Extract'!C2 -> 60 | H2: ='BST Extract'!D2 -> 40 | I2: ='BST Extract'!E2 -> 55 | J2: ='BST Extract'!F2 -> 35 | K2: ='BST Extract'!G2 -> 65 | L2: ='BST Extract'!H2 -> 85 | M2: ='BST Extract'!I2 -> 340 | N2: SPECIAL_DEFENSE | O2: 1 | T2: =N2&","&O2&","&P2&","&Q2&","&R2&","&S2 -> SPECIAL_DEFENSE,1,,,, | U2: ='Ability Extract'!C2 -> LEVITATE | V2: ='Ability Extract'!D2 -> WHITESMOKE | W2: ='Ability Extract'!E2 -> MAGMAARMOR | X2: ='Ability Extract'!F2 -> LEVITATE,WHITESMOKE,MAGMAARMOR | Y2: =VLOOKUP($A2,'Moves Species'!$A:$E,3,FALSE) -> 1, DEFENSECURL, 1, SMOG, 4, EMBER, 6, POISONGAS, 9, FIRESPIN, 12, HAZE, 15, CLEARSMOG, 18, INCINERATE, 22, CORRODE, 26, FLAMEBURST, 29, SCALD, 32, MIASMA, 35, LAVAPLUME, 38, CORROSIVEGAS, 41, SLUDGEBOMB, 44, FLAMETHROWER, 47, TOXIC, 50, ACIDRAIN, 53, INFERNO, 56, STEAMERUPTION, 60, ERUPTION, | Z2: =VLOOKUP($A2,'Moves Species'!$A:$E,4,FALSE) -> ACIDRAIN, ACROBATICS, AIRSLASH, ATTRACT, BATTERYACID, BODYPRESS, BODYSLAM, BOUNCE, CAUSTICACID, CLEARSMOG, CORROSIVEGAS, DARKPULSE, DAZZLINGGLEAM, DUNEBLAST, DUSTDEVILS, EARTHPOWER, ENERGYBALL, FIREBLAST, FLAMECHARGE, FLAMETHROWER, FLAMEVOLLEY, FLAREBLITZ, FLUXWAVE, GAMMARAY, GASTROACID, GEOMANCY, GIGADRAIN, GOLDRUSH, GOSSIP, GUNKSHOT, GYROBALL, HAZE, HEATWAVE, HIDDENPOWER, INCINERATE, IRONDEFENSE, IRONHEAD, LOVEBURST, MEMENTO, MIASMA, MUDSHACKLES, MUDSLIDE, MYSTICALFIRE, NASTYPLOT, PROTECT, QUICKSAND, RAYOFLIGHT, REST, RETURN, ROCKBLAST, ROCKSLIDE, ROCKTOMB, SANDSTORM, SANDTOMB, SCALD, SCORCHINGSANDS, SLEEPTALK, SLUDGEBOMB, SLUDGEWAVE, STEALTHROCK, STEAMERUPTION, STRANGESTEAM, SUNNYDAY, TAUNT, TERRAINPULSE, TOXIC, VENOMDRAIN, WILDFIRE, WORKUP, | AA2: =VLOOKUP($A2,'Moves Species'!$A:$E,5,FALSE) -> CURSE, HEATCRASH, ALKALINEBOMB, SIZZLE, FIERYDANCE, FIREBLAST, DESTINYBOND, HYDROSTEAM, FIREWALL, | AB2: WEEZING | AC2: Level | AD2: 33
A3: =A2+1 -> 2 | B3: [WEEZING] | C3: Weezing | D3: ='BST Extract'!J3 -> FIRE | E3: ='BST Extract'!K3 -> POISON | F3: =D3&","&E3 -> FIRE,POISON | G3: ='BST Extract'!C3 -> 85 | H3: ='BST Extract'!D3 -> 55 | I3: ='BST Extract'!E3 -> 85 | J3: ='BST Extract'!F3 -> 60 | K3: ='BST Extract'!G3 -> 95 | L3: ='BST Extract'!H3 -> 110 | M3: ='BST Extract'!I3 -> 490 | N3: SPECIAL_DEFENSE | O3: 2 | T3: =N3&","&O3&","&P3&","&Q3&","&R3&","&S3 -> SPECIAL_DEFENSE,2,,,, | U3: ='Ability Extract'!C3 -> LEVITATE | V3: ='Ability Extract'!D3 -> WHITESMOKE | W3: ='Ability Extract'!E3 -> MAGMAARMOR | X3: ='Ability Extract'!F3 -> LEVITATE,WHITESMOKE,MAGMAARMOR | Y3: =VLOOKUP($A3,'Moves Species'!$A:$E,3,FALSE) -> 0, WILLOWISP, 1, WILLOWISP, 1, DEFENSECURL, 1, SMOG, 4, EMBER, 6, POISONGAS, 9, FIRESPIN, 12, HAZE, 15, CLEARSMOG, 18, INCINERATE, 22, CORRODE, 26, FLAMEBURST, 29, SCALD, 32, MIASMA, 35, LAVAPLUME, 38, CORROSIVEGAS, 41, SLUDGEBOMB, 44, FLAMETHROWER, 47, TOXIC, 50, ACIDRAIN, 53, INFERNO, 56, STEAMERUPTION, 60, ERUPTION, | Z3: =VLOOKUP($A3,'Moves Species'!$A:$E,4,FALSE) -> ACIDRAIN, ACROBATICS, AIRSLASH, ATTRACT, BATTERYACID, BODYPRESS, BODYSLAM, BOUNCE, CAUSTICACID, CLEARSMOG, CORROSIVEGAS, DARKPULSE, DAZZLINGGLEAM, DUNEBLAST, DUSTDEVILS, EARTHPOWER, ENERGYBALL, FIREBLAST, FLAMECHARGE, FLAMETHROWER, FLAMEVOLLEY, FLAREBLITZ, FLUXWAVE, GAMMARAY, GASTROACID, GEOMANCY, GIGADRAIN, GOLDRUSH, GOSSIP, GUNKSHOT, GYROBALL, HAZE, HEATWAVE, HIDDENPOWER, INCINERATE, IRONDEFENSE, IRONHEAD, LOVEBURST, MEMENTO, MIASMA, MUDSHACKLES, MUDSLIDE, MYSTICALFIRE, NASTYPLOT, PROTECT, QUICKSAND, RAYOFLIGHT, REST, RETURN, ROCKBLAST, ROCKSLIDE, ROCKTOMB, SANDSTORM, SANDTOMB, SCALD, SCORCHINGSANDS, SLEEPTALK, SLUDGEBOMB, SLUDGEWAVE, STEALTHROCK, STEAMERUPTION, STRANGESTEAM, SUNNYDAY, TAUNT, TERRAINPULSE, TOXIC, VENOMDRAIN, WILDFIRE, WORKUP, | AA3: =VLOOKUP($A3,'Moves Species'!$A:$E,5,FALSE) -> 0
A4: =A3+1 -> 3 | B4: [SOLOSIS] | C4: Solosis | D4: ='BST Extract'!J4 -> WATER | E4: ='BST Extract'!K4 -> PSYCHIC | F4: =D4&","&E4 -> WATER,PSYCHIC | G4: ='BST Extract'!C4 -> 45 | H4: ='BST Extract'!D4 -> 20 | I4: ='BST Extract'!E4 -> 60 | J4: ='BST Extract'!F4 -> 20 | K4: ='BST Extract'!G4 -> 85 | L4: ='BST Extract'!H4 -> 60 | M4: ='BST Extract'!I4 -> 290 | N4: SPECIAL_ATTACK | O4: 1 | T4: =N4&","&O4&","&P4&","&Q4&","&R4&","&S4 -> SPECIAL_ATTACK,1,,,, | U4: ='Ability Extract'!C4 -> SWIFTSWIM | V4: ='Ability Extract'!D4 -> MAGICBOUNCE | W4: ='Ability Extract'!E4 -> TECHNICIAN | X4: ='Ability Extract'!F4 -> SWIFTSWIM,MAGICBOUNCE,TECHNICIAN | Y4: =VLOOKUP($A4,'Moves Species'!$A:$E,3,FALSE) -> 1, CONFUSION, 1, WATERSPORT, 4, BUBBLE, 7, QUICKSPELL, 10, HEALBLOCK, 13, ARCANEBLAST, 16, WATERPULSE, 19, SOAK, 22, PSYBEAM, 25, DRENCH, 28, REFLECT, 28, LIGHTSCREEN, 31, WISH, 34, PSYSHOCK, 37, OCEANBLAST, 40, CALMMIND, 43, PSYCHIC, 46, TIDALWAVE, 49, STOREDPOWER, 52, TRICKROOM, 56, HYDROPUMP, 60, PSYCHOBOOST, | Z4: =VLOOKUP($A4,'Moves Species'!$A:$E,4,FALSE) -> ALLERGY, ARCANEENERGY, ATTRACT, AURASPHERE, BATTLEOFWITS, BLIZZARD, BRINE, CALMMIND, CASCADE, CHARGEBEAM, CHIDORI, CHILLINGTOUCH, CLEANSE, CONFUSERAY, COSMICPOWER, COVET, CURSE, DARKPULSE, DAZZLINGGLEAM, DEFOG, DRAININGKISS, EARTHPOWER, ENERGYBALL, FLIPTURN, FLUXWAVE, GAMMARAY, GIGADRAIN, HAIL, HAZE, HEX, HEXBOLT, HIDDENPOWER, HYPERVOICE, ICEBEAM, ICEPUNCH, ICICLESPEAR, ICYWIND, LIGHTSCREEN, MAGICROOM, METRONOME, MINDDRAIN, MINDMELD, MISSILESHOT, MIST, MIXEDWAVES, MYSTICPULSE, NASTYPLOT, NUMBINGWIND, OCEANWRATH, OVERFLOW, PHOBIA, PIXIEDUST, PROTECT, PSYCHIC, PSYCHICTERRAIN, RAINDANCE, REFLECT, REST, RETURN, SAFEGUARD, SCALD, SIGNALBEAM, SLEEPTALK, SOAK, STRANGESTEAM, SUBMERGE, SUBSTITUTE, TERRAINPULSE, THUNDERWAVE, TIDALWAVE, TOXIC, TRIATTACK, VOLTSWITCH, WAIL, WATERPRESSURE, WATERPULSE, WHIRLPOOL, WISH, WONDERROOM, | AA4: =VLOOKUP($A4,'Moves Species'!$A:$E,5,FALSE) -> ACIDARMOR, GUARDSWAP, POWERSWAP, SPEEDSWAP, TRICK, BUBBLEBEAM, HYPNOSIS, KARMASPELL, FREEZEDRY, EXTRASENSORY, MUDDYWATER, | AB4: DUOSION | AC4: Level | AD4: 27
A5: =A4+1 -> 4 | B5: [DUOSION] | C5: Duosion | D5: ='BST Extract'!J5 -> WATER | E5: ='BST Extract'!K5 -> PSYCHIC | F5: =D5&","&E5 -> WATER,PSYCHIC | G5: ='BST Extract'!C5 -> 60 | H5: ='BST Extract'!D5 -> 35 | I5: ='BST Extract'!E5 -> 70 | J5: ='BST Extract'!F5 -> 35 | K5: ='BST Extract'!G5 -> 100 | L5: ='BST Extract'!H5 -> 70 | M5: ='BST Extract'!I5 -> 370 | N5: SPECIAL_ATTACK | O5: 2 | T5: =N5&","&O5&","&P5&","&Q5&","&R5&","&S5 -> SPECIAL_ATTACK,2,,,, | U5: ='Ability Extract'!C5 -> SWIFTSWIM | V5: ='Ability Extract'!D5 -> MAGICBOUNCE | W5: ='Ability Extract'!E5 -> TECHNICIAN | X5: ='Ability Extract'!F5 -> SWIFTSWIM,MAGICBOUNCE,TECHNICIAN | Y5: =VLOOKUP($A5,'Moves Species'!$A:$E,3,FALSE) -> 0, CHECKMATE, 1, CHECKMATE, 1, CONFUSION, 1, WATERSPORT, 4, BUBBLE, 7, QUICKSPELL, 10, HEALBLOCK, 13, ARCANEBLAST, 16, WATERPULSE, 19, SOAK, 22, PSYBEAM, 25, DRENCH, 28, REFLECT, 28, LIGHTSCREEN, 31, WISH, 34, PSYSHOCK, 37, OCEANBLAST, 40, CALMMIND, 43, PSYCHIC, 46, TIDALWAVE, 49, STOREDPOWER, 52, TRICKROOM, 56, HYDROPUMP, 60, PSYCHOBOOST, | Z5: =VLOOKUP($A5,'Moves Species'!$A:$E,4,FALSE) -> ALLERGY, ARCANEENERGY, ATTRACT, AURASPHERE, BATTLEOFWITS, BLIZZARD, BRINE, CALMMIND, CASCADE, CHARGEBEAM, CHIDORI, CHILLINGTOUCH, CLEANSE, CONFUSERAY, COSMICPOWER, COVET, CURSE, DARKPULSE, DAZZLINGGLEAM, DEFOG, DRAININGKISS, EARTHPOWER, ENERGYBALL, FLIPTURN, FLUXWAVE, GAMMARAY, GIGADRAIN, HAIL, HAZE, HEX, HEXBOLT, HIDDENPOWER, HYPERVOICE, ICEBEAM, ICEPUNCH, ICICLESPEAR, ICYWIND, LIGHTSCREEN, MAGICROOM, METRONOME, MINDDRAIN, MINDMELD, MISSILESHOT, MIST, MIXEDWAVES, MYSTICPULSE, NASTYPLOT, NUMBINGWIND, OCEANWRATH, OVERFLOW, PHOBIA, PIXIEDUST, PROTECT, PSYCHIC, PSYCHICTERRAIN, RAINDANCE, REFLECT, REST, RETURN, SAFEGUARD, SCALD, SIGNALBEAM, SLEEPTALK, SOAK, STRANGESTEAM, SUBMERGE, SUBSTITUTE, TERRAINPULSE, THUNDERWAVE, TIDALWAVE, TOXIC, TRIATTACK, VOLTSWITCH, WAIL, WATERPRESSURE, WATERPULSE, WHIRLPOOL, WISH, WONDERROOM, | AA5: =VLOOKUP($A5,'Moves Species'!$A:$E,5,FALSE) -> 0 | AB5: REUNICLUS | AC5: Level | AD5: 41
A6: =A5+1 -> 5 | B6: [REUNICLUS] | C6: Reuniclus | D6: ='BST Extract'!J6 -> WATER | E6: ='BST Extract'!K6 -> PSYCHIC | F6: =D6&","&E6 -> WATER,PSYCHIC | G6: ='BST Extract'!C6 -> 70 | H6: ='BST Extract'!D6 -> 40 | I6: ='BST Extract'!E6 -> 95 | J6: ='BST Extract'!F6 -> 60 | K6: ='BST Extract'!G6 -> 130 | L6: ='BST Extract'!H6 -> 95 | M6: ='BST Extract'!I6 -> 490 | N6: SPECIAL_ATTACK | O6: 3 | T6: =N6&","&O6&","&P6&","&Q6&","&R6&","&S6 -> SPECIAL_ATTACK,3,,,, | U6: ='Ability Extract'!C6 -> SWIFTSWIM | V6: ='Ability Extract'!D6 -> MAGICBOUNCE | W6: ='Ability Extract'!E6 -> TECHNICIAN | X6: ='Ability Extract'!F6 -> SWIFTSWIM,MAGICBOUNCE,TECHNICIAN | Y6: =VLOOKUP($A6,'Moves Species'!$A:$E,3,FALSE) -> 1, CHECKMATE, 1, CONFUSION, 1, WATERSPORT, 4, BUBBLE, 7, QUICKSPELL, 10, HEALBLOCK, 13, ARCANEBLAST, 16, WATERPULSE, 19, SOAK, 22, PSYBEAM, 25, DRENCH, 28, REFLECT, 28, LIGHTSCREEN, 31, WISH, 34, PSYSHOCK, 37, OCEANBLAST, 40, CALMMIND, 43, PSYCHIC, 46, TIDALWAVE, 49, STOREDPOWER, 52, TRICKROOM, 56, HYDROPUMP, 60, PSYCHOBOOST, | Z6: =VLOOKUP($A6,'Moves Species'!$A:$E,4,FALSE) -> ALLERGY, ARCANEENERGY, ATTRACT, AURASPHERE, BATTLEOFWITS, BLIZZARD, BRINE, CALMMIND, CASCADE, CHARGEBEAM, CHIDORI, CHILLINGTOUCH, CLEANSE, CONFUSERAY, COSMICPOWER, COVET, CURSE, DARKPULSE, DAZZLINGGLEAM, DEFOG, DRAININGKISS, EARTHPOWER, ENERGYBALL, FLIPTURN, FLUXWAVE, GAMMARAY, GIGADRAIN, HAIL, HAZE, HEX, HEXBOLT, HIDDENPOWER, HYPERVOICE, ICEBEAM, ICEPUNCH, ICICLESPEAR, ICYWIND, LIGHTSCREEN, MAGICROOM, METRONOME, MINDDRAIN, MINDMELD, MISSILESHOT, MIST, MIXEDWAVES, MYSTICPULSE, NASTYPLOT, NUMBINGWIND, OCEANWRATH, OVERFLOW, PHOBIA, PIXIEDUST, PROTECT, PSYCHIC, PSYCHICTERRAIN, RAINDANCE, REFLECT, REST, RETURN, SAFEGUARD, SCALD, SIGNALBEAM, SLEEPTALK, SOAK, STRANGESTEAM, SUBMERGE, SUBSTITUTE, TERRAINPULSE, THUNDERWAVE, TIDALWAVE, TOXIC, TRIATTACK, VOLTSWITCH, WAIL, WATERPRESSURE, WATERPULSE, WHIRLPOOL, WISH, WONDERROOM, | AA6: =VLOOKUP($A6,'Moves Species'!$A:$E,5,FALSE) -> 0
A7: =A6+1 -> 6 | B7: [GASTLY] | C7: Gastly | D7: ='BST Extract'!J7 -> ICE | E7: ='BST Extract'!K7 -> FLYING | F7: =D7&","&E7 -> ICE,FLYING | G7: ='BST Extract'!C7 -> 30 | H7: ='BST Extract'!D7 -> 30 | I7: ='BST Extract'!E7 -> 30 | J7: ='BST Extract'!F7 -> 85 | K7: ='BST Extract'!G7 -> 100 | L7: ='BST Extract'!H7 -> 35 | M7: ='BST Extract'!I7 -> 310 | N7: SPECIAL_ATTACK | O7: 1 | T7: =N7&","&O7&","&P7&","&Q7&","&R7&","&S7 -> SPECIAL_ATTACK,1,,,, | U7: ='Ability Extract'!C7 -> FILTER | V7: ='Ability Extract'!D7 -> CLOUDNINE | W7: ='Ability Extract'!E7 -> CURSEDBODY | X7: ='Ability Extract'!F7 -> FILTER,CLOUDNINE,CURSEDBODY | Y7: =VLOOKUP($A7,'Moves Species'!$A:$E,3,FALSE) -> 1, ICEVORTEX, 1, COLDFRONT, 1, POWDERSNOW, 4, GALEHOLD, 8, MIST, 11, HAIL, 15, ICYWIND, 18, AIRCUTTER, 21, HYPOTHERMIA, 24, DEFOG, 27, EROSION, 30, NUMBINGWIND, 33, STARDUSTREVERIE, 36, TORNADO, 39, FROSTBREATH, 42, ICEBEAM, 45, AERIALPULSE, 48, WEATHERBALL, 52, BOREASBREATH, 56, TAILWIND, 60, BLIZZARD, | Z7: =VLOOKUP($A7,'Moves Species'!$A:$E,4,FALSE) -> ACIDRAIN, AERIALACE, AERIALPULSE, AIRSLASH, AMBUSH, ASTRALWIND, ATTRACT, BLIZZARD, BONECHILL, BRINE, CALMMIND, CHARGEBEAM, CHILLINGTOUCH, CLEARSMOG, DAZZLINGGLEAM, DEFOG, DRAGONGALE, DUSTDEVILS, ECHOEDVOICE, FLUXWAVE, FROSTBITE, GENESIS, GOSSIP, HAIL, HAZE, HIDDENPOWER, HURRICANE, HYPERVOICE, HYPOTHERMIA, ICEBEAM, ICEFANG, ICEHAMMER, ICEPUNCH, ICICLESPEAR, ICICLESTRIKE, ICYWIND, LIQUIDATION, MIRRORSHOT, MIST, MOONBLAST, MYSTICPULSE, NASTYPLOT, NEBULASTRIKE, NUMBINGWIND, OCEANWRATH, PIXIEDUST, PROTECT, QUICKGUARD, RAINDANCE, RAYOFLIGHT, REST, RETURN, SCALD, SIGNALBEAM, SLEEPTALK, SOAK, STRANGESTEAM, SWITCHEROO, TAILWIND, TEMPESTFLARE, TERRAINPULSE, TORNADO, TOXIC, TURBULENCE, WAIL, WATERPULSE, WEATHERBALL, WHIRLPOOL, WISH, | AA7: =VLOOKUP($A7,'Moves Species'!$A:$E,5,FALSE) -> AURORAVEIL, HURRICANE, RAINDANCE, TRIATTACK, FROZENHEART, LIQUIDNITROGEN, CHECKMATE, MEMENTO, BONECHILL, SNOWFLAKES, | AB7: HAUNTER | AC7: Level | AD7: 25
A8: =A7+1 -> 7 | B8: [HAUNTER] | C8: Haunter | D8: ='BST Extract'!J8 -> ICE | E8: ='BST Extract'!K8 -> FLYING | F8: =D8&","&E8 -> ICE,FLYING | G8: ='BST Extract'!C8 -> 50 | H8: ='BST Extract'!D8 -> 45 | I8: ='BST Extract'!E8 -> 45 | J8: ='BST Extract'!F8 -> 95 | K8: ='BST Extract'!G8 -> 115 | L8: ='BST Extract'!H8 -> 55 | M8: ='BST Extract'!I8 -> 405 | N8: SPECIAL_ATTACK | O8: 2 | T8: =N8&","&O8&","&P8&","&Q8&","&R8&","&S8 -> SPECIAL_ATTACK,2,,,, | U8: ='Ability Extract'!C8 -> FILTER | V8: ='Ability Extract'!D8 -> CLOUDNINE | W8: ='Ability Extract'!E8 -> SNOWWARNING | X8: ='Ability Extract'!F8 -> FILTER,CLOUDNINE,SNOWWARNING | Y8: =VLOOKUP($A8,'Moves Species'!$A:$E,3,FALSE) -> 0, AIRSLASH, 1, AIRSLASH, 1, ICEVORTEX, 1, COLDFRONT, 1, POWDERSNOW, 4, GALEHOLD, 8, MIST, 11, HAIL, 15, ICYWIND, 18, AIRCUTTER, 21, HYPOTHERMIA, 24, DEFOG, 27, EROSION, 30, NUMBINGWIND, 33, STARDUSTREVERIE, 36, TORNADO, 39, FROSTBREATH, 42, ICEBEAM, 45, AERIALPULSE, 48, WEATHERBALL, 52, BOREASBREATH, 56, TAILWIND, 60, BLIZZARD, | Z8: =VLOOKUP($A8,'Moves Species'!$A:$E,4,FALSE) -> ACIDRAIN, AERIALACE, AERIALPULSE, AIRSLASH, AMBUSH, ASTRALWIND, ATTRACT, BLIZZARD, BONECHILL, BRINE, CALMMIND, CHARGEBEAM, CHILLINGTOUCH, CLEARSMOG, DAZZLINGGLEAM, DEFOG, DRAGONGALE, DUSTDEVILS, ECHOEDVOICE, FLUXWAVE, FROSTBITE, GENESIS, GOSSIP, HAIL, HAZE, HIDDENPOWER, HURRICANE, HYPERVOICE, HYPOTHERMIA, ICEBEAM, ICEFANG, ICEHAMMER, ICEPUNCH, ICICLESPEAR, ICICLESTRIKE, ICYWIND, LIQUIDATION, MIRRORSHOT, MIST, MOONBLAST, MYSTICPULSE, NASTYPLOT, NEBULASTRIKE, NUMBINGWIND, OCEANWRATH, PIXIEDUST, PROTECT, QUICKGUARD, RAINDANCE, RAYOFLIGHT, REST, RETURN, SCALD, SIGNALBEAM, SLEEPTALK, SOAK, STRANGESTEAM, SWITCHEROO, TAILWIND, TEMPESTFLARE, TERRAINPULSE, TORNADO, TOXIC, TURBULENCE, WAIL, WATERPULSE, WEATHERBALL, WHIRLPOOL, WISH, | AA8: =VLOOKUP($A8,'Moves Species'!$A:$E,5,FALSE) -> 0 | AB8: GENGAR | AC8: Item | AD8: WINDSTONE
A9: =A8+1 -> 8 | B9: [GENGAR] | C9: Gengar | D9: ='BST Extract'!J9 -> ICE | E9: ='BST Extract'!K9 -> FLYING | F9: =D9&","&E9 -> ICE,FLYING | G9: ='BST Extract'!C9 -> 65 | H9: ='BST Extract'!D9 -> 60 | I9: ='BST Extract'!E9 -> 60 | J9: ='BST Extract'!F9 -> 115 | K9: ='BST Extract'!G9 -> 130 | L9: ='BST Extract'!H9 -> 70 | M9: ='BST Extract'!I9 -> 500 | N9: SPECIAL_ATTACK | O9: 3 | T9: =N9&","&O9&","&P9&","&Q9&","&R9&","&S9 -> SPECIAL_ATTACK,3,,,, | U9: ='Ability Extract'!C9 -> FILTER | V9: ='Ability Extract'!D9 -> CLOUDNINE | W9: ='Ability Extract'!E9 -> SNOWWARNING | X9: ='Ability Extract'!F9 -> FILTER,CLOUDNINE,SNOWWARNING | Y9: =VLOOKUP($A9,'Moves Species'!$A:$E,3,FALSE) -> 0, FREEZEDRY, 1, FREEZEDRY, 1, AIRSLASH, 1, ICEVORTEX, 1, COLDFRONT, 1, POWDERSNOW, 4, GALEHOLD, 8, MIST, 11, HAIL, 15, ICYWIND, 18, AIRCUTTER, 21, HYPOTHERMIA, 24, DEFOG, 27, EROSION, 30, NUMBINGWIND, 33, STARDUSTREVERIE, 36, TORNADO, 39, FROSTBREATH, 42, ICEBEAM, 45, AERIALPULSE, 48, WEATHERBALL, 52, BOREASBREATH, 56, TAILWIND, 60, BLIZZARD, | Z9: =VLOOKUP($A9,'Moves Species'!$A:$E,4,FALSE) -> ACIDRAIN, AERIALACE, AERIALPULSE, AIRSLASH, AMBUSH, ASTRALWIND, ATTRACT, BLIZZARD, BONECHILL, BRINE, CALMMIND, CHARGEBEAM, CHILLINGTOUCH, CLEARSMOG, DAZZLINGGLEAM, DEFOG, DRAGONGALE, DUSTDEVILS, ECHOEDVOICE, FLUXWAVE, FROSTBITE, GENESIS, GOSSIP, HAIL, HAZE, HIDDENPOWER, HURRICANE, HYPERVOICE, HYPOTHERMIA, ICEBEAM, ICEFANG, ICEHAMMER, ICEPUNCH, ICICLESPEAR, ICICLESTRIKE, ICYWIND, LIQUIDATION, MIRRORSHOT, MIST, MOONBLAST, MYSTICPULSE, NASTYPLOT, NEBULASTRIKE, NUMBINGWIND, OCEANWRATH, PIXIEDUST, PROTECT, QUICKGUARD, RAINDANCE, RAYOFLIGHT, REST, RETURN, SCALD, SIGNALBEAM, SLEEPTALK, SOAK, STRANGESTEAM, SWITCHEROO, TAILWIND, TEMPESTFLARE, TERRAINPULSE, TORNADO, TOXIC, TURBULENCE, WAIL, WATERPULSE, WEATHERBALL, WHIRLPOOL, WISH, | AA9: =VLOOKUP($A9,'Moves Species'!$A:$E,5,FALSE) -> 0
A10: =A9+1 -> 9 | B10: [DODUO] | C10: Doduo | D10: ='BST Extract'!J10 -> COSMIC | E10: ='BST Extract'!K10 -> FLYING | F10: =D10&","&E10 -> COSMIC,FLYING | G10: ='BST Extract'!C10 -> 60 | H10: ='BST Extract'!D10 -> 35 | I10: ='BST Extract'!E10 -> 35 | J10: ='BST Extract'!F10 -> 75 | K10: ='BST Extract'!G10 -> 75 | L10: ='BST Extract'!H10 -> 60 | M10: ='BST Extract'!I10 -> 340 | N10: SPEED | O10: 1 | T10: =N10&","&O10&","&P10&","&Q10&","&R10&","&S10 -> SPEED,1,,,, | U10: ='Ability Extract'!C10 -> EARLYBIRD | V10: ='Ability Extract'!D10 -> COMPETITIVE | W10: ='Ability Extract'!E10 -> DISHEARTEN | X10: ='Ability Extract'!F10 -> EARLYBIRD,COMPETITIVE,DISHEARTEN | Y10: =VLOOKUP($A10,'Moves Species'!$A:$E,3,FALSE) -> 1, RADIATION, 1, STARDUST, 4, GUST, 7, CONFUSION, 10, SWIFT, 13, BLACKOUT, 16, TURBULENCE, 19, STARFALL, 23, HYPNOSIS, 26, PSYBEAM, 29, AIRSLASH, 33, COSMICPOWER, 36, TWINSTARS, 39, PSYBLAST, 42, AERIALPULSE, 45, MOONLIGHT, 48, MOONBLAST, 52, ARCANEENERGY, 56, TEMPESTFLARE, 60, METEORBEAM, | Z10: =VLOOKUP($A10,'Moves Species'!$A:$E,4,FALSE) -> AERIALACE, AERIALPULSE, AIRSLASH, ANTIMATTER, ARCANEENERGY, ASTEROIDBELT, ASTRALWIND, ATTRACT, AURASPHERE, BATTLEOFWITS, CALMMIND, CHIDORI, COACHING, COSMICAVATAR, COSMICPOWER, COVET, DARKPULSE, DAZZLINGGLEAM, DEFOG, DRAGONGALE, DRILLPECK, DUALWINGBEAT, ECLIPSENOVA, ENDERSHOCK, EXPANDINGFORCE, FABLEDRUSH, FEATHERDANCE, FLUXWAVE, FOCUSBLAST, GAMMARAY, GHASTLYFLOOD, GOSSIP, HEX, HEXBOLT, HIDDENPOWER, HYPERVOICE, KAMEHAMEHA, KNOCKOFF, LIGHTSCREEN, LOVEBURST, METEORBEAM, MINDMELD, MIRRORSHOT, MIXEDWAVES, MOONBLAST, MOONSTONERAY, MYSTICPULSE, NASTYPLOT, NEBULASTRIKE, PHOBIA, PIXIEDUST, PROTECT, PSYCHIC, PSYCHICTERRAIN, PURGE, REFLECT, REST, RETURN, ROUND, SAFEGUARD, SATELLITERAY, SHADOWBALL, SIGNALBEAM, SLASH, SLEEPTALK, SOLARECLIPSE, SOULRIP, STARDUSTREVERIE, STELLARRUSH, STRANGESTEAM, SUBSTITUTE, SWIFT, TAILWIND, TEMPESTFLARE, TOXIC, TRIATTACK, TURBULENCE, UMBRALWAVE, WISH, WONDERROOM, ZENHEADBUTT, | AA10: =VLOOKUP($A10,'Moves Species'!$A:$E,5,FALSE) -> FEATHERDANCE, REFLECT, LIGHTSCREEN, STOREDPOWER, BRAVEBIRD, TAILWIND, WISH, METEORSHOWER, FUTURESIGHT, | AB10: DODRIO | AC10: Item | AD10: MOONSTONE
A11: =A10+1 -> 10 | B11: [DODRIO] | C11: Dodrio | D11: ='BST Extract'!J11 -> COSMIC | E11: ='BST Extract'!K11 -> FLYING | F11: =D11&","&E11 -> COSMIC,FLYING | G11: ='BST Extract'!C11 -> 80 | H11: ='BST Extract'!D11 -> 60 | I11: ='BST Extract'!E11 -> 60 | J11: ='BST Extract'!F11 -> 105 | K11: ='BST Extract'!G11 -> 100 | L11: ='BST Extract'!H11 -> 85 | M11: ='BST Extract'!I11 -> 490 | N11: SPEED | O11: 2 | T11: =N11&","&O11&","&P11&","&Q11&","&R11&","&S11 -> SPEED,2,,,, | U11: ='Ability Extract'!C11 -> EARLYBIRD | V11: ='Ability Extract'!D11 -> COMPETITIVE | W11: ='Ability Extract'!E11 -> DISHEARTEN | X11: ='Ability Extract'!F11 -> EARLYBIRD,COMPETITIVE,DISHEARTEN | Y11: =VLOOKUP($A11,'Moves Species'!$A:$E,3,FALSE) -> 0, STARSALIGNED, 1, STARSALIGNED, 1, TRIATTACK, 1, RADIATION, 1, STARDUST, 4, GUST, 7, CONFUSION, 10, SWIFT, 13, BLACKOUT, 16, TURBULENCE, 19, STARFALL, 23, HYPNOSIS, 26, PSYBEAM, 29, AIRSLASH, 33, COSMICPOWER, 36, TWINSTARS, 39, PSYBLAST, 42, AERIALPULSE, 45, MOONLIGHT, 48, MOONBLAST, 52, ARCANEENERGY, 56, TEMPESTFLARE, 60, METEORBEAM, | Z11: =VLOOKUP($A11,'Moves Species'!$A:$E,4,FALSE) -> AERIALACE, AERIALPULSE, AIRSLASH, ANTIMATTER, ARCANEENERGY, ASTEROIDBELT, ASTRALWIND, ATTRACT, AURASPHERE, BATTLEOFWITS, CALMMIND, CHIDORI, COACHING, COSMICAVATAR, COSMICPOWER, COVET, DARKPULSE, DAZZLINGGLEAM, DEFOG, DRAGONGALE, DRILLPECK, DUALWINGBEAT, ECLIPSENOVA, ENDERSHOCK, EXPANDINGFORCE, FABLEDRUSH, FEATHERDANCE, FLUXWAVE, FOCUSBLAST, GAMMARAY, GHASTLYFLOOD, GOSSIP, HEX, HEXBOLT, HIDDENPOWER, HYPERVOICE, KAMEHAMEHA, KNOCKOFF, LIGHTSCREEN, LOVEBURST, METEORBEAM, MINDMELD, MIRRORSHOT, MIXEDWAVES, MOONBLAST, MOONSTONERAY, MYSTICPULSE, NASTYPLOT, NEBULASTRIKE, PHOBIA, PIXIEDUST, PROTECT, PSYCHIC, PSYCHICTERRAIN, PURGE, REFLECT, REST, RETURN, ROUND, SAFEGUARD, SATELLITERAY, SHADOWBALL, SIGNALBEAM, SLASH, SLEEPTALK, SOLARECLIPSE, SOULRIP, STARDUSTREVERIE, STELLARRUSH, STRANGESTEAM, SUBSTITUTE, SWIFT, TAILWIND, TEMPESTFLARE, TOXIC, TRIATTACK, TURBULENCE, UMBRALWAVE, WISH, WONDERROOM, ZENHEADBUTT, | AA11: =VLOOKUP($A11,'Moves Species'!$A:$E,5,FALSE) -> 0
A12: =A11+1 -> 11 | B12: [EKANS] | C12: Ekans | D12: ='BST Extract'!J12 -> GROUND | E12: ='BST Extract'!K12 -> POISON | F12: =D12&","&E12 -> GROUND,POISON | G12: ='BST Extract'!C12 -> 40 | H12: ='BST Extract'!D12 -> 70 | I12: ='BST Extract'!E12 -> 44 | J12: ='BST Extract'!F12 -> 60 | K12: ='BST Extract'!G12 -> 40 | L12: ='BST Extract'!H12 -> 54 | M12: ='BST Extract'!I12 -> 308 | N12: ATTACK | O12: 1 | T12: =N12&","&O12&","&P12&","&Q12&","&R12&","&S12 -> ATTACK,1,,,, | U12: ='Ability Extract'!C12 -> CORROSION | V12: ='Ability Extract'!D12 -> SANDSPIT | W12: ='Ability Extract'!E12 -> LEECHINGFANGS | X12: ='Ability Extract'!F12 -> CORROSION,SANDSPIT,LEECHINGFANGS | Y12: =VLOOKUP($A12,'Moves Species'!$A:$E,3,FALSE) -> 1, WRAP, 1, LEER, 1, SANDJET, 4, POISONSTING, 8, BITE, 11, STEAMROLLER, 14, TOXICTHREAD, 17, POISONFANG, 20, BULLDOZE, 23, HYPNOSIS, 26, POISONTAIL, 29, DIG, 32, VENOMDRAIN, 35, CRUNCH, 38, LEECHLIFE, 41, NEUROTOXIN, 44, THOUSANDWAVES, 47, TOXIC, 50, COIL, 53, PLAGUE, 56, CONTINENTALRIFT, 60, GUNKSHOT, | Z12: =VLOOKUP($A12,'Moves Species'!$A:$E,4,FALSE) -> ALLERGY, AMBUSH, ANCIENTGLARE, ATTRACT, BULLDOZE, BULLETSEED, CAUSTICACID, CLEARSMOG, CONFUSERAY, COUPDEGRACE, COVET, CRUELWHIP, CRUNCH, DARKPULSE, DEFENDORDER, DRAGONBLOOD, DRAGONHAMMER, DUNEBLAST, DUSTDEVILS, EARTHENLANCE, EARTHPOWER, EARTHQUAKE, ENDERSHOCK, EXECUTION, FALSESWIPE, FIREFANG, FURYCUTTER, GAIAPULSE, GOBLINSTRIKE, GOSSIP, HIDDENPOWER, ICEFANG, KNOCKOFF, LASHOUT, LEECHLIFE, MIASMA, MINDDRAIN, MUDSHACKLES, MUDSLIDE, NASTYPLOT, OBSIDIANSHARDS, OUTRAGE, PERCUSSIONBLAST, PLAYROUGH, POISONFANG, POISONJAB, POWERWHIP, PROTECT, PSYCHICFANGS, QUICKSAND, REST, RETURN, ROCKBLAST, ROCKSLIDE, ROCKTOMB, ROUND, SANDSTORM, SANDTOMB, SCORCHINGSANDS, SEISMICCHANT, SLEEPTALK, SLUDGEBOMB, SLUDGEWAVE, SONICBLAST, SPIKES, STEALTHROCK, STONEEDGE, SUNNYDAY, SWITCHEROO, SWORDSDANCE, TAUNT, TERRAINPULSE, THUNDERFANG, TOXIC, TOXICSPIKES, VENDETTA, VENOMDRAIN, VITALITYDRAIN, WEAKSPOT, WORKUP, ZENHEADBUTT, | AA12: =VLOOKUP($A12,'Moves Species'!$A:$E,5,FALSE) -> SWORDSDANCE, DRAGONTAIL, NAGASKIN, KNOCKOFF, CLANGINGSCALES, QUICKSAND, VENOMDRENCH, SCREECH, DRAGONGNAW, SCALESTORM, | AB12: ARBOK | AC12: Level | AD12: 30
