Workbook

Sheet Rune Listing
A1: Rune Number | B1: Diablo 2 Rune Equivalent | C1: Corresponding SS2 Ability | F1: Rune | G1: S | H1: A | I1: B | J1: C | K1: D
A2: 1 | B2: El | C2: Liquid Ooze | F2: =UPPER(SUBSTITUTE(C2," ","")) -> LIQUIDOOZE | G2: =INDEX(Formatted!$A$2:$F$331, MATCH($F2, Formatted!$A$2:$A$331, 0), 2) | H2: =INDEX(Formatted!$A$2:$F$331, MATCH($F2, Formatted!$A$2:$A$331, 0), 3) | I2: =INDEX(Formatted!$A$2:$F$331, MATCH($F2, Formatted!$A$2:$A$331, 0), 4) | J2: =INDEX(Formatted!$A$2:$F$331, MATCH($F2, Formatted!$A$2:$A$331, 0), 5) -> C | K2: =INDEX(Formatted!$A$2:$F$331, MATCH($F2, Formatted!$A$2:$A$331, 0), 6) | L2: : | M2: ="RUNE"&TEXT(A2,"0#")&"_"&TEXT(UPPER(F2),"general") -> RUNE01_LIQUIDOOZE | N2: , | O2: =L2&M2&N2 -> :RUNE01_LIQUIDOOZE, | P2: =O2&O3&O4&O5&O6&O7&O8&O9&O10&O11&O12 -> :RUNE01_LIQUIDOOZE, :RUNE02_AFTERMATH, :RUNE03_SANDVEIL, :RUNE04_SNOWCLOAK, :RUNE05_VITALSPIRIT, :RUNE06_SYNCHRONIZE, :RUNE07_UNNERVE, :RUNE08_POISONPOINT, :RUNE09_NATURALCURE, :RUNE10_HEALER, :RUNE11_ICEBODY, | Q2: =P2&P13&P24 -> :RUNE01_LIQUIDOOZE, :RUNE02_AFTERMATH, :RUNE03_SANDVEIL, :RUNE04_SNOWCLOAK, :RUNE05_VITALSPIRIT, :RUNE06_SYNCHRONIZE, :RUNE07_UNNERVE, :RUNE08_POISONPOINT, :RUNE09_NATURALCURE, :RUNE10_HEALER, :RUNE11_ICEBODY, :RUNE12_CLAYFORM, :RUNE13_SYNTHESIZE, :RUNE14_RAINDISH, :RUNE15_BATTLEARMOR, :RUNE16_FLAMEBODY, :RUNE17_MOLDBREAKER, :RUNE18_SHIELDDUST, :RUNE19_INFILTRATOR, :RUNE20_ANALYTIC, :RUNE21_STATIC, :RUNE22_COMPOUNDEYES, :RUNE23_TOUGHCLAWS, :RUNE24_RIVALRY, :RUNE25_SNIPER, :RUNE26_IMPENETRABLE, :RUNE27_TELEPATHY, :RUNE28_GOOEY, :RUNE29_INNERFOCUS, :RUNE30_PRISMARMOR, :RUNE31_ARENATRAP, :RUNE32_CLEARBODY, :RUNE33_PASTELVEIL,
A3: =A2+1 -> 2 | B3: Eld | C3: Aftermath | F3: =UPPER(SUBSTITUTE(C3," ","")) -> AFTERMATH | G3: =INDEX(Formatted!$A$2:$F$331, MATCH($F3, Formatted!$A$2:$A$331, 0), 2) | H3: =INDEX(Formatted!$A$2:$F$331, MATCH($F3, Formatted!$A$2:$A$331, 0), 3) | I3: =INDEX(Formatted!$A$2:$F$331, MATCH($F3, Formatted!$A$2:$A$331, 0), 4) | J3: =INDEX(Formatted!$A$2:$F$331, MATCH($F3, Formatted!$A$2:$A$331, 0), 5) -> C | K3: =INDEX(Formatted!$A$2:$F$331, MATCH($F3, Formatted!$A$2:$A$331, 0), 6) | L3: : | M3: ="RUNE"&TEXT(A3,"0#")&"_"&TEXT(UPPER(F3),"general") -> RUNE02_AFTERMATH | N3: , | O3: =L3&M3&N3 -> :RUNE02_AFTERMATH,
A4: =A3+1 -> 3 | B4: Tir | C4: Sand Veil | F4: =UPPER(SUBSTITUTE(C4," ","")) -> SANDVEIL | G4: =INDEX(Formatted!$A$2:$F$331, MATCH($F4, Formatted!$A$2:$A$331, 0), 2) | H4: =INDEX(Formatted!$A$2:$F$331, MATCH($F4, Formatted!$A$2:$A$331, 0), 3) | I4: =INDEX(Formatted!$A$2:$F$331, MATCH($F4, Formatted!$A$2:$A$331, 0), 4) | J4: =INDEX(Formatted!$A$2:$F$331, MATCH($F4, Formatted!$A$2:$A$331, 0), 5) -> C | K4: =INDEX(Formatted!$A$2:$F$331, MATCH($F4, Formatted!$A$2:$A$331, 0), 6) | L4: : | M4: ="RUNE"&TEXT(A4,"0#")&"_"&TEXT(UPPER(F4),"general") -> RUNE03_SANDVEIL | N4: , | O4: =L4&M4&N4 -> :RUNE03_SANDVEIL,
A5: =A4+1 -> 4 | B5: Nef | C5: Snow Cloak | F5: =UPPER(SUBSTITUTE(C5," ","")) -> SNOWCLOAK | G5: =INDEX(Formatted!$A$2:$F$331, MATCH($F5, Formatted!$A$2:$A$331, 0), 2) | H5: =INDEX(Formatted!$A$2:$F$331, MATCH($F5, Formatted!$A$2:$A$331, 0), 3) | I5: =INDEX(Formatted!$A$2:$F$331, MATCH($F5, Formatted!$A$2:$A$331, 0), 4) | J5: =INDEX(Formatted!$A$2:$F$331, MATCH($F5, Formatted!$A$2:$A$331, 0), 5) -> C | K5: =INDEX(Formatted!$A$2:$F$331, MATCH($F5, Formatted!$A$2:$A$331, 0), 6) | L5: : | M5: ="RUNE"&TEXT(A5,"0#")&"_"&TEXT(UPPER(F5),"general") -> RUNE04_SNOWCLOAK | N5: , | O5: =L5&M5&N5 -> :RUNE04_SNOWCLOAK,
A6: =A5+1 -> 5 | B6: Eth | C6: Vital Spirit | F6: =UPPER(SUBSTITUTE(C6," ","")) -> VITALSPIRIT | G6: =INDEX(Formatted!$A$2:$F$331, MATCH($F6, Formatted!$A$2:$A$331, 0), 2) | H6: =INDEX(Formatted!$A$2:$F$331, MATCH($F6, Formatted!$A$2:$A$331, 0), 3) | I6: =INDEX(Formatted!$A$2:$F$331, MATCH($F6, Formatted!$A$2:$A$331, 0), 4) | J6: =INDEX(Formatted!$A$2:$F$331, MATCH($F6, Formatted!$A$2:$A$331, 0), 5) -> C | K6: =INDEX(Formatted!$A$2:$F$331, MATCH($F6, Formatted!$A$2:$A$331, 0), 6) | L6: : | M6: ="RUNE"&TEXT(A6,"0#")&"_"&TEXT(UPPER(F6),"general") -> RUNE05_VITALSPIRIT | N6: , | O6: =L6&M6&N6 -> :RUNE05_VITALSPIRIT,
A7: =A6+1 -> 6 | B7: Ith | C7: Synchronize | F7: =UPPER(SUBSTITUTE(C7," ","")) -> SYNCHRONIZE | G7: =INDEX(Formatted!$A$2:$F$331, MATCH($F7, Formatted!$A$2:$A$331, 0), 2) | H7: =INDEX(Formatted!$A$2:$F$331, MATCH($F7, Formatted!$A$2:$A$331, 0), 3) | I7: =INDEX(Formatted!$A$2:$F$331, MATCH($F7, Formatted!$A$2:$A$331, 0), 4) | J7: =INDEX(Formatted!$A$2:$F$331, MATCH($F7, Formatted!$A$2:$A$331, 0), 5) -> C | K7: =INDEX(Formatted!$A$2:$F$331, MATCH($F7, Formatted!$A$2:$A$331, 0), 6) | L7: : | M7: ="RUNE"&TEXT(A7,"0#")&"_"&TEXT(UPPER(F7),"general") -> RUNE06_SYNCHRONIZE | N7: , | O7: =L7&M7&N7 -> :RUNE06_SYNCHRONIZE,
A8: =A7+1 -> 7 | B8: Tal | C8: Unnerve | F8: =UPPER(SUBSTITUTE(C8," ","")) -> UNNERVE | G8: =INDEX(Formatted!$A$2:$F$331, MATCH($F8, Formatted!$A$2:$A$331, 0), 2) | H8: =INDEX(Formatted!$A$2:$F$331, MATCH($F8, Formatted!$A$2:$A$331, 0), 3) | I8: =INDEX(Formatted!$A$2:$F$331, MATCH($F8, Formatted!$A$2:$A$331, 0), 4) | J8: =INDEX(Formatted!$A$2:$F$331, MATCH($F8, Formatted!$A$2:$A$331, 0), 5) -> C | K8: =INDEX(Formatted!$A$2:$F$331, MATCH($F8, Formatted!$A$2:$A$331, 0), 6) | L8: : | M8: ="RUNE"&TEXT(A8,"0#")&"_"&TEXT(UPPER(F8),"general") -> RUNE07_UNNERVE | N8: , | O8: =L8&M8&N8 -> :RUNE07_UNNERVE,
A9: =A8+1 -> 8 | B9: Ral | C9: Poison Point | F9: =UPPER(SUBSTITUTE(C9," ","")) -> POISONPOINT | G9: =INDEX(Formatted!$A$2:$F$331, MATCH($F9, Formatted!$A$2:$A$331, 0), 2) | H9: =INDEX(Formatted!$A$2:$F$331, MATCH($F9, Formatted!$A$2:$A$331, 0), 3) | I9: =INDEX(Formatted!$A$2:$F$331, MATCH($F9, Formatted!$A$2:$A$331, 0), 4) | J9: =INDEX(Formatted!$A$2:$F$331, MATCH($F9, Formatted!$A$2:$A$331, 0), 5) -> C | K9: =INDEX(Formatted!$A$2:$F$331, MATCH($F9, Formatted!$A$2:$A$331, 0), 6) | L9: : | M9: ="RUNE"&TEXT(A9,"0#")&"_"&TEXT(UPPER(F9),"general") -> RUNE08_POISONPOINT | N9: , | O9: =L9&M9&N9 -> :RUNE08_POISONPOINT,
A10: =A9+1 -> 9 | B10: Ort | C10: Natural Cure | F10: =UPPER(SUBSTITUTE(C10," ","")) -> NATURALCURE | G10: =INDEX(Formatted!$A$2:$F$331, MATCH($F10, Formatted!$A$2:$A$331, 0), 2) | H10: =INDEX(Formatted!$A$2:$F$331, MATCH($F10, Formatted!$A$2:$A$331, 0), 3) | I10: =INDEX(Formatted!$A$2:$F$331, MATCH($F10, Formatted!$A$2:$A$331, 0), 4) | J10: =INDEX(Formatted!$A$2:$F$331, MATCH($F10, Formatted!$A$2:$A$331, 0), 5) -> C | K10: =INDEX(Formatted!$A$2:$F$331, MATCH($F10, Formatted!$A$2:$A$331, 0), 6) | L10: : | M10: ="RUNE"&TEXT(A10,"0#")&"_"&TEXT(UPPER(F10),"general") -> RUNE09_NATURALCURE | N10: , | O10: =L10&M10&N10 -> :RUNE09_NATURALCURE,
A11: =A10+1 -> 10 | B11: Thul | C11: Healer | F11: =UPPER(SUBSTITUTE(C11," ","")) -> HEALER | G11: =INDEX(Formatted!$A$2:$F$331, MATCH($F11, Formatted!$A$2:$A$331, 0), 2) | H11: =INDEX(Formatted!$A$2:$F$331, MATCH($F11, Formatted!$A$2:$A$331, 0), 3) | I11: =INDEX(Formatted!$A$2:$F$331, MATCH($F11, Formatted!$A$2:$A$331, 0), 4) | J11: =INDEX(Formatted!$A$2:$F$331, MATCH($F11, Formatted!$A$2:$A$331, 0), 5) -> C | K11: =INDEX(Formatted!$A$2:$F$331, MATCH($F11, Formatted!$A$2:$A$331, 0), 6) | L11: : | M11: ="RUNE"&TEXT(A11,"0#")&"_"&TEXT(UPPER(F11),"general") -> RUNE10_HEALER | N11: , | O11: =L11&M11&N11 -> :RUNE10_HEALER,
A12: =A11+1 -> 11 | B12: Amn | C12: Ice Body | F12: =UPPER(SUBSTITUTE(C12," ","")) -> ICEBODY | G12: =INDEX(Formatted!$A$2:$F$331, MATCH($F12, Formatted!$A$2:$A$331, 0), 2) | H12: =INDEX(Formatted!$A$2:$F$331, MATCH($F12, Formatted!$A$2:$A$331, 0), 3) | I12: =INDEX(Formatted!$A$2:$F$331, MATCH($F12, Formatted!$A$2:$A$331, 0), 4) | J12: =INDEX(Formatted!$A$2:$F$331, MATCH($F12, Formatted!$A$2:$A$331, 0), 5) -> C | K12: =INDEX(Formatted!$A$2:$F$331, MATCH($F12, Formatted!$A$2:$A$331, 0), 6) | L12: : | M12: ="RUNE"&TEXT(A12,"0#")&"_"&TEXT(UPPER(F12),"general") -> RUNE11_ICEBODY | N12: , | O12: =L12&M12&N12 -> :RUNE11_ICEBODY,
A13: =A12+1 -> 12 | B13: Sol | C13: Clay Form | F13: =UPPER(SUBSTITUTE(C13," ","")) -> CLAYFORM | G13: =INDEX(Formatted!$A$2:$F$331, MATCH($F13, Formatted!$A$2:$A$331, 0), 2) | H13: =INDEX(Formatted!$A$2:$F$331, MATCH($F13, Formatted!$A$2:$A$331, 0), 3) | I13: =INDEX(Formatted!$A$2:$F$331, MATCH($F13, Formatted!$A$2:$A$331, 0), 4) | J13: =INDEX(Formatted!$A$2:$F$331, MATCH($F13, Formatted!$A$2:$A$331, 0), 5) -> C | K13: =INDEX(Formatted!$A$2:$F$331, MATCH($F13, Formatted!$A$2:$A$331, 0), 6) | L13: : | M13: ="RUNE"&TEXT(A13,"0#")&"_"&TEXT(UPPER(F13),"general") -> RUNE12_CLAYFORM | N13: , | O13: =L13&M13&N13 -> :RUNE12_CLAYFORM, | P13: =O13&O14&O15&O16&O17&O18&O19&O20&O21&O22&O23 -> :RUNE12_CLAYFORM, :RUNE13_SYNTHESIZE, :RUNE14_RAINDISH, :RUNE15_BATTLEARMOR, :RUNE16_FLAMEBODY, :RUNE17_MOLDBREAKER, :RUNE18_SHIELDDUST, :RUNE19_INFILTRATOR, :RUNE20_ANALYTIC, :RUNE21_STATIC, :RUNE22_COMPOUNDEYES,
A14: =A13+1 -> 13 | B14: Shael | C14: Synthesize | F14: =UPPER(SUBSTITUTE(C14," ","")) -> SYNTHESIZE | G14: =INDEX(Formatted!$A$2:$F$331, MATCH($F14, Formatted!$A$2:$A$331, 0), 2) | H14: =INDEX(Formatted!$A$2:$F$331, MATCH($F14, Formatted!$A$2:$A$331, 0), 3) | I14: =INDEX(Formatted!$A$2:$F$331, MATCH($F14, Formatted!$A$2:$A$331, 0), 4) | J14: =INDEX(Formatted!$A$2:$F$331, MATCH($F14, Formatted!$A$2:$A$331, 0), 5) -> C | K14: =INDEX(Formatted!$A$2:$F$331, MATCH($F14, Formatted!$A$2:$A$331, 0), 6) | L14: : | M14: ="RUNE"&TEXT(A14,"0#")&"_"&TEXT(UPPER(F14),"general") -> RUNE13_SYNTHESIZE | N14: , | O14: =L14&M14&N14 -> :RUNE13_SYNTHESIZE,
A15: =A14+1 -> 14 | B15: Dol | C15: Rain Dish | F15: =UPPER(SUBSTITUTE(C15," ","")) -> RAINDISH | G15: =INDEX(Formatted!$A$2:$F$331, MATCH($F15, Formatted!$A$2:$A$331, 0), 2) | H15: =INDEX(Formatted!$A$2:$F$331, MATCH($F15, Formatted!$A$2:$A$331, 0), 3) | I15: =INDEX(Formatted!$A$2:$F$331, MATCH($F15, Formatted!$A$2:$A$331, 0), 4) | J15: =INDEX(Formatted!$A$2:$F$331, MATCH($F15, Formatted!$A$2:$A$331, 0), 5) -> C | K15: =INDEX(Formatted!$A$2:$F$331, MATCH($F15, Formatted!$A$2:$A$331, 0), 6) | L15: : | M15: ="RUNE"&TEXT(A15,"0#")&"_"&TEXT(UPPER(F15),"general") -> RUNE14_RAINDISH | N15: , | O15: =L15&M15&N15 -> :RUNE14_RAINDISH,
A16: =A15+1 -> 15 | B16: Hel | C16: Battle Armor | F16: =UPPER(SUBSTITUTE(C16," ","")) -> BATTLEARMOR | G16: =INDEX(Formatted!$A$2:$F$331, MATCH($F16, Formatted!$A$2:$A$331, 0), 2) | H16: =INDEX(Formatted!$A$2:$F$331, MATCH($F16, Formatted!$A$2:$A$331, 0), 3) | I16: =INDEX(Formatted!$A$2:$F$331, MATCH($F16, Formatted!$A$2:$A$331, 0), 4) | J16: =INDEX(Formatted!$A$2:$F$331, MATCH($F16, Formatted!$A$2:$A$331, 0), 5) -> C | K16: =INDEX(Formatted!$A$2:$F$331, MATCH($F16, Formatted!$A$2:$A$331, 0), 6) | L16: : | M16: ="RUNE"&TEXT(A16,"0#")&"_"&TEXT(UPPER(F16),"general") -> RUNE15_BATTLEARMOR | N16: , | O16: =L16&M16&N16 -> :RUNE15_BATTLEARMOR,
A17: =A16+1 -> 16 | B17: Io | C17: Flame Body | F17: =UPPER(SUBSTITUTE(C17," ","")) -> FLAMEBODY | G17: =INDEX(Formatted!$A$2:$F$331, MATCH($F17, Formatted!$A$2:$A$331, 0), 2) | H17: =INDEX(Formatted!$A$2:$F$331, MATCH($F17, Formatted!$A$2:$A$331, 0), 3) | I17: =INDEX(Formatted!$A$2:$F$331, MATCH($F17, Formatted!$A$2:$A$331, 0), 4) | J17: =INDEX(Formatted!$A$2:$F$331, MATCH($F17, Formatted!$A$2:$A$331, 0), 5) -> C | K17: =INDEX(Formatted!$A$2:$F$331, MATCH($F17, Formatted!$A$2:$A$331, 0), 6) | L17: : | M17: ="RUNE"&TEXT(A17,"0#")&"_"&TEXT(UPPER(F17),"general") -> RUNE16_FLAMEBODY | N17: , | O17: =L17&M17&N17 -> :RUNE16_FLAMEBODY,
A18: =A17+1 -> 17 | B18: Lum | C18: Mold Breaker | F18: =UPPER(SUBSTITUTE(C18," ","")) -> MOLDBREAKER | G18: =INDEX(Formatted!$A$2:$F$331, MATCH($F18, Formatted!$A$2:$A$331, 0), 2) | H18: =INDEX(Formatted!$A$2:$F$331, MATCH($F18, Formatted!$A$2:$A$331, 0), 3) | I18: =INDEX(Formatted!$A$2:$F$331, MATCH($F18, Formatted!$A$2:$A$331, 0), 4) | J18: =INDEX(Formatted!$A$2:$F$331, MATCH($F18, Formatted!$A$2:$A$331, 0), 5) -> C | K18: =INDEX(Formatted!$A$2:$F$331, MATCH($F18, Formatted!$A$2:$A$331, 0), 6) | L18: : | M18: ="RUNE"&TEXT(A18,"0#")&"_"&TEXT(UPPER(F18),"general") -> RUNE17_MOLDBREAKER | N18: , | O18: =L18&M18&N18 -> :RUNE17_MOLDBREAKER,
A19: =A18+1 -> 18 | B19: Ko | C19: Shield Dust | F19: =UPPER(SUBSTITUTE(C19," ","")) -> SHIELDDUST | G19: =INDEX(Formatted!$A$2:$F$331, MATCH($F19, Formatted!$A$2:$A$331, 0), 2) | H19: =INDEX(Formatted!$A$2:$F$331, MATCH($F19, Formatted!$A$2:$A$331, 0), 3) | I19: =INDEX(Formatted!$A$2:$F$331, MATCH($F19, Formatted!$A$2:$A$331, 0), 4) | J19: =INDEX(Formatted!$A$2:$F$331, MATCH($F19, Formatted!$A$2:$A$331, 0), 5) -> C | K19: =INDEX(Formatted!$A$2:$F$331, MATCH($F19, Formatted!$A$2:$A$331, 0), 6) | L19: : | M19: ="RUNE"&TEXT(A19,"0#")&"_"&TEXT(UPPER(F19),"general") -> RUNE18_SHIELDDUST | N19: , | O19: =L19&M19&N19 -> :RUNE18_SHIELDDUST,
A20: =A19+1 -> 19 | B20: Fal | C20: Infiltrator | F20: =UPPER(SUBSTITUTE(C20," ","")) -> INFILTRATOR | G20: =INDEX(Formatted!$A$2:$F$331, MATCH($F20, Formatted!$A$2:$A$331, 0), 2) | H20: =INDEX(Formatted!$A$2:$F$331, MATCH($F20, Formatted!$A$2:$A$331, 0), 3) | I20: =INDEX(Formatted!$A$2:$F$331, MATCH($F20, Formatted!$A$2:$A$331, 0), 4) | J20: =INDEX(Formatted!$A$2:$F$331, MATCH($F20, Formatted!$A$2:$A$331, 0), 5) -> C | K20: =INDEX(Formatted!$A$2:$F$331, MATCH($F20, Formatted!$A$2:$A$331, 0), 6) | L20: : | M20: ="RUNE"&TEXT(A20,"0#")&"_"&TEXT(UPPER(F20),"general") -> RUNE19_INFILTRATOR | N20: , | O20: =L20&M20&N20 -> :RUNE19_INFILTRATOR,
A21: =A20+1 -> 20 | B21: Lem | C21: Analytic | F21: =UPPER(SUBSTITUTE(C21," ","")) -> ANALYTIC | G21: =INDEX(Formatted!$A$2:$F$331, MATCH($F21, Formatted!$A$2:$A$331, 0), 2) | H21: =INDEX(Formatted!$A$2:$F$331, MATCH($F21, Formatted!$A$2:$A$331, 0), 3) | I21: =INDEX(Formatted!$A$2:$F$331, MATCH($F21, Formatted!$A$2:$A$331, 0), 4) | J21: =INDEX(Formatted!$A$2:$F$331, MATCH($F21, Formatted!$A$2:$A$331, 0), 5) -> C | K21: =INDEX(Formatted!$A$2:$F$331, MATCH($F21, Formatted!$A$2:$A$331, 0), 6) | L21: : | M21: ="RUNE"&TEXT(A21,"0#")&"_"&TEXT(UPPER(F21),"general") -> RUNE20_ANALYTIC | N21: , | O21: =L21&M21&N21 -> :RUNE20_ANALYTIC,
A22: =A21+1 -> 21 | B22: Pul | C22: Static | F22: =UPPER(SUBSTITUTE(C22," ","")) -> STATIC | G22: =INDEX(Formatted!$A$2:$F$331, MATCH($F22, Formatted!$A$2:$A$331, 0), 2) | H22: =INDEX(Formatted!$A$2:$F$331, MATCH($F22, Formatted!$A$2:$A$331, 0), 3) | I22: =INDEX(Formatted!$A$2:$F$331, MATCH($F22, Formatted!$A$2:$A$331, 0), 4) | J22: =INDEX(Formatted!$A$2:$F$331, MATCH($F22, Formatted!$A$2:$A$331, 0), 5) -> C | K22: =INDEX(Formatted!$A$2:$F$331, MATCH($F22, Formatted!$A$2:$A$331, 0), 6) | L22: : | M22: ="RUNE"&TEXT(A22,"0#")&"_"&TEXT(UPPER(F22),"general") -> RUNE21_STATIC | N22: , | O22: =L22&M22&N22 -> :RUNE21_STATIC,
A23: =A22+1 -> 22 | B23: Um | C23: Compound Eyes | F23: =UPPER(SUBSTITUTE(C23," ","")) -> COMPOUNDEYES | G23: =INDEX(Formatted!$A$2:$F$331, MATCH($F23, Formatted!$A$2:$A$331, 0), 2) | H23: =INDEX(Formatted!$A$2:$F$331, MATCH($F23, Formatted!$A$2:$A$331, 0), 3) | I23: =INDEX(Formatted!$A$2:$F$331, MATCH($F23, Formatted!$A$2:$A$331, 0), 4) | J23: =INDEX(Formatted!$A$2:$F$331, MATCH($F23, Formatted!$A$2:$A$331, 0), 5) -> C | K23: =INDEX(Formatted!$A$2:$F$331, MATCH($F23, Formatted!$A$2:$A$331, 0), 6) | L23: : | M23: ="RUNE"&TEXT(A23,"0#")&"_"&TEXT(UPPER(F23),"general") -> RUNE22_COMPOUNDEYES | N23: , | O23: =L23&M23&N23 -> :RUNE22_COMPOUNDEYES,
A24: =A23+1 -> 23 | B24: Mal | C24: Tough Claws | F24: =UPPER(SUBSTITUTE(C24," ","")) -> TOUGHCLAWS | G24: =INDEX(Formatted!$A$2:$F$331, MATCH($F24, Formatted!$A$2:$A$331, 0), 2) | H24: =INDEX(Formatted!$A$2:$F$331, MATCH($F24, Formatted!$A$2:$A$331, 0), 3) | I24: =INDEX(Formatted!$A$2:$F$331, MATCH($F24, Formatted!$A$2:$A$331, 0), 4) | J24: =INDEX(Formatted!$A$2:$F$331, MATCH($F24, Formatted!$A$2:$A$331, 0), 5) -> C | K24: =INDEX(Formatted!$A$2:$F$331, MATCH($F24, Formatted!$A$2:$A$331, 0), 6) | L24: : | M24: ="RUNE"&TEXT(A24,"0#")&"_"&TEXT(UPPER(F24),"general") -> RUNE23_TOUGHCLAWS | N24: , | O24: =L24&M24&N24 -> :RUNE23_TOUGHCLAWS, | P24: =O24&O25&O26&O27&O28&O29&O30&O31&O32&O33&O34 -> :RUNE23_TOUGHCLAWS, :RUNE24_RIVALRY, :RUNE25_SNIPER, :RUNE26_IMPENETRABLE, :RUNE27_TELEPATHY, :RUNE28_GOOEY, :RUNE29_INNERFOCUS, :RUNE30_PRISMARMOR, :RUNE31_ARENATRAP, :RUNE32_CLEARBODY, :RUNE33_PASTELVEIL,
A25: =A24+1 -> 24 | B25: Ist | C25: Rivalry | F25: =UPPER(SUBSTITUTE(C25," ","")) -> RIVALRY | G25: =INDEX(Formatted!$A$2:$F$331, MATCH($F25, Formatted!$A$2:$A$331, 0), 2) | H25: =INDEX(Formatted!$A$2:$F$331, MATCH($F25, Formatted!$A$2:$A$331, 0), 3) | I25: =INDEX(Formatted!$A$2:$F$331, MATCH($F25, Formatted!$A$2:$A$331, 0), 4) | J25: =INDEX(Formatted!$A$2:$F$331, MATCH($F25, Formatted!$A$2:$A$331, 0), 5) -> C | K25: =INDEX(Formatted!$A$2:$F$331, MATCH($F25, Formatted!$A$2:$A$331, 0), 6) | L25: : | M25: ="RUNE"&TEXT(A25,"0#")&"_"&TEXT(UPPER(F25),"general") -> RUNE24_RIVALRY | N25: , | O25: =L25&M25&N25 -> :RUNE24_RIVALRY,
A26: =A25+1 -> 25 | B26: Gul | C26: Sniper | F26: =UPPER(SUBSTITUTE(C26," ","")) -> SNIPER | G26: =INDEX(Formatted!$A$2:$F$331, MATCH($F26, Formatted!$A$2:$A$331, 0), 2) | H26: =INDEX(Formatted!$A$2:$F$331, MATCH($F26, Formatted!$A$2:$A$331, 0), 3) | I26: =INDEX(Formatted!$A$2:$F$331, MATCH($F26, Formatted!$A$2:$A$331, 0), 4) | J26: =INDEX(Formatted!$A$2:$F$331, MATCH($F26, Formatted!$A$2:$A$331, 0), 5) -> C | K26: =INDEX(Formatted!$A$2:$F$331, MATCH($F26, Formatted!$A$2:$A$331, 0), 6) | L26: : | M26: ="RUNE"&TEXT(A26,"0#")&"_"&TEXT(UPPER(F26),"general") -> RUNE25_SNIPER | N26: , | O26: =L26&M26&N26 -> :RUNE25_SNIPER,
A27: =A26+1 -> 26 | B27: Vex | C27: Impenetrable | F27: =UPPER(SUBSTITUTE(C27," ","")) -> IMPENETRABLE | G27: =INDEX(Formatted!$A$2:$F$331, MATCH($F27, Formatted!$A$2:$A$331, 0), 2) | H27: =INDEX(Formatted!$A$2:$F$331, MATCH($F27, Formatted!$A$2:$A$331, 0), 3) | I27: =INDEX(Formatted!$A$2:$F$331, MATCH($F27, Formatted!$A$2:$A$331, 0), 4) | J27: =INDEX(Formatted!$A$2:$F$331, MATCH($F27, Formatted!$A$2:$A$331, 0), 5) -> C | K27: =INDEX(Formatted!$A$2:$F$331, MATCH($F27, Formatted!$A$2:$A$331, 0), 6) | L27: : | M27: ="RUNE"&TEXT(A27,"0#")&"_"&TEXT(UPPER(F27),"general") -> RUNE26_IMPENETRABLE | N27: , | O27: =L27&M27&N27 -> :RUNE26_IMPENETRABLE,
A28: =A27+1 -> 27 | B28: Ohm | C28: Telepathy | F28: =UPPER(SUBSTITUTE(C28," ","")) -> TELEPATHY | G28: =INDEX(Formatted!$A$2:$F$331, MATCH($F28, Formatted!$A$2:$A$331, 0), 2) | H28: =INDEX(Formatted!$A$2:$F$331, MATCH($F28, Formatted!$A$2:$A$331, 0), 3) | I28: =INDEX(Formatted!$A$2:$F$331, MATCH($F28, Formatted!$A$2:$A$331, 0), 4) | J28: =INDEX(Formatted!$A$2:$F$331, MATCH($F28, Formatted!$A$2:$A$331, 0), 5) -> C | K28: =INDEX(Formatted!$A$2:$F$331, MATCH($F28, Formatted!$A$2:$A$331, 0), 6) | L28: : | M28: ="RUNE"&TEXT(A28,"0#")&"_"&TEXT(UPPER(F28),"general") -> RUNE27_TELEPATHY | N28: , | O28: =L28&M28&N28 -> :RUNE27_TELEPATHY,
A29: =A28+1 -> 28 | B29: Lo | C29: Gooey | F29: =UPPER(SUBSTITUTE(C29," ","")) -> GOOEY | G29: =INDEX(Formatted!$A$2:$F$331, MATCH($F29, Formatted!$A$2:$A$331, 0), 2) | H29: =INDEX(Formatted!$A$2:$F$331, MATCH($F29, Formatted!$A$2:$A$331, 0), 3) | I29: =INDEX(Formatted!$A$2:$F$331, MATCH($F29, Formatted!$A$2:$A$331, 0), 4) -> B | J29: =INDEX(Formatted!$A$2:$F$331, MATCH($F29, Formatted!$A$2:$A$331, 0), 5) | K29: =INDEX(Formatted!$A$2:$F$331, MATCH($F29, Formatted!$A$2:$A$331, 0), 6) | L29: : | M29: ="RUNE"&TEXT(A29,"0#")&"_"&TEXT(UPPER(F29),"general") -> RUNE28_GOOEY | N29: , | O29: =L29&M29&N29 -> :RUNE28_GOOEY,
A30: =A29+1 -> 29 | B30: Sur | C30: Inner Focus | F30: =UPPER(SUBSTITUTE(C30," ","")) -> INNERFOCUS | G30: =INDEX(Formatted!$A$2:$F$331, MATCH($F30, Formatted!$A$2:$A$331, 0), 2) | H30: =INDEX(Formatted!$A$2:$F$331, MATCH($F30, Formatted!$A$2:$A$331, 0), 3) | I30: =INDEX(Formatted!$A$2:$F$331, MATCH($F30, Formatted!$A$2:$A$331, 0), 4) -> B | J30: =INDEX(Formatted!$A$2:$F$331, MATCH($F30, Formatted!$A$2:$A$331, 0), 5) | K30: =INDEX(Formatted!$A$2:$F$331, MATCH($F30, Formatted!$A$2:$A$331, 0), 6) | L30: : | M30: ="RUNE"&TEXT(A30,"0#")&"_"&TEXT(UPPER(F30),"general") -> RUNE29_INNERFOCUS | N30: , | O30: =L30&M30&N30 -> :RUNE29_INNERFOCUS,
A31: =A30+1 -> 30 | B31: Ber | C31: Prism Armor | F31: =UPPER(SUBSTITUTE(C31," ","")) -> PRISMARMOR | G31: =INDEX(Formatted!$A$2:$F$331, MATCH($F31, Formatted!$A$2:$A$331, 0), 2) | H31: =INDEX(Formatted!$A$2:$F$331, MATCH($F31, Formatted!$A$2:$A$331, 0), 3) | I31: =INDEX(Formatted!$A$2:$F$331, MATCH($F31, Formatted!$A$2:$A$331, 0), 4) -> B | J31: =INDEX(Formatted!$A$2:$F$331, MATCH($F31, Formatted!$A$2:$A$331, 0), 5) | K31: =INDEX(Formatted!$A$2:$F$331, MATCH($F31, Formatted!$A$2:$A$331, 0), 6) | L31: : | M31: ="RUNE"&TEXT(A31,"0#")&"_"&TEXT(UPPER(F31),"general") -> RUNE30_PRISMARMOR | N31: , | O31: =L31&M31&N31 -> :RUNE30_PRISMARMOR,
A32: =A31+1 -> 31 | B32: Jah | C32: Arena Trap | F32: =UPPER(SUBSTITUTE(C32," ","")) -> ARENATRAP | G32: =INDEX(Formatted!$A$2:$F$331, MATCH($F32, Formatted!$A$2:$A$331, 0), 2) | H32: =INDEX(Formatted!$A$2:$F$331, MATCH($F32, Formatted!$A$2:$A$331, 0), 3) -> A | I32: =INDEX(Formatted!$A$2:$F$331, MATCH($F32, Formatted!$A$2:$A$331, 0), 4) | J32: =INDEX(Formatted!$A$2:$F$331, MATCH($F32, Formatted!$A$2:$A$331, 0), 5) | K32: =INDEX(Formatted!$A$2:$F$331, MATCH($F32, Formatted!$A$2:$A$331, 0), 6) | L32: : | M32: ="RUNE"&TEXT(A32,"0#")&"_"&TEXT(UPPER(F32),"general") -> RUNE31_ARENATRAP | N32: , | O32: =L32&M32&N32 -> :RUNE31_ARENATRAP,
A33: =A32+1 -> 32 | B33: Cham | C33: Clear Body | F33: =UPPER(SUBSTITUTE(C33," ","")) -> CLEARBODY | G33: =INDEX(Formatted!$A$2:$F$331, MATCH($F33, Formatted!$A$2:$A$331, 0), 2) | H33: =INDEX(Formatted!$A$2:$F$331, MATCH($F33, Formatted!$A$2:$A$331, 0), 3) -> A | I33: =INDEX(Formatted!$A$2:$F$331, MATCH($F33, Formatted!$A$2:$A$331, 0), 4) | J33: =INDEX(Formatted!$A$2:$F$331, MATCH($F33, Formatted!$A$2:$A$331, 0), 5) | K33: =INDEX(Formatted!$A$2:$F$331, MATCH($F33, Formatted!$A$2:$A$331, 0), 6) | L33: : | M33: ="RUNE"&TEXT(A33,"0#")&"_"&TEXT(UPPER(F33),"general") -> RUNE32_CLEARBODY | N33: , | O33: =L33&M33&N33 -> :RUNE32_CLEARBODY,
A34: =A33+1 -> 33 | B34: Zod | C34: Pastel Veil | F34: =UPPER(SUBSTITUTE(C34," ","")) -> PASTELVEIL | G34: =INDEX(Formatted!$A$2:$F$331, MATCH($F34, Formatted!$A$2:$A$331, 0), 2) -> S | H34: =INDEX(Formatted!$A$2:$F$331, MATCH($F34, Formatted!$A$2:$A$331, 0), 3) | I34: =INDEX(Formatted!$A$2:$F$331, MATCH($F34, Formatted!$A$2:$A$331, 0), 4) | J34: =INDEX(Formatted!$A$2:$F$331, MATCH($F34, Formatted!$A$2:$A$331, 0), 5) | K34: =INDEX(Formatted!$A$2:$F$331, MATCH($F34, Formatted!$A$2:$A$331, 0), 6) | L34: : | M34: ="RUNE"&TEXT(A34,"0#")&"_"&TEXT(UPPER(F34),"general") -> RUNE33_PASTELVEIL | N34: , | O34: =L34&M34&N34 -> :RUNE33_PASTELVEIL,

Sheet Formatted
A1: Ability Listing | B1: NO | C1: Maybe but probably not | D1: Fine for the most part | E1: Completely Fine | F1: Doesn't Matter
A2: LEVITATE | B2: S
A3: INTIMIDATE | B3: S
A4: STATIC | E4: C
A5: MOXIE | C5: A
A6: TELEPATHY | E6: C
A7: FLAMEBODY | E7: C
A8: INFILTRATOR | E8: C
A9: RAINDISH | E9: C
A10: SOLIDROCK | C10: A
A11: RECKLESS | E11: C
A12: WATERABSORB | B12: S
A13: PRANKSTER | B13: S
A14: DRYSKIN | B14: S
A15: OBLIVIOUS | E15: C
A16: SHEERFORCE | E16: C
A17: DEFIANT | B17: S
A18: OVERCOAT | F18: D
A19: SHIELDDUST | E19: C
A20: THICKFAT | B20: S
A21: POISONTOUCH | E21: C
A22: ANALYTIC | E22: C
A23: STRONGJAW | C23: A
A24: ROUGHSKIN | F24: D
A25: SWARM | B25: S
A26: CACOPHONY | B26: S
A27: SPEEDBOOST | B27: S
A28: GLUTTONY | F28: D
A29: MAGICGUARD | B29: S
A30: CURSEDBODY | B30: S
A31: WONDERSKIN | C31: A
A32: LONGREACH | F32: D
A33: DAZZLING | B33: S
A34: STURDY | B34: S
A35: CLOUDNINE | C35: A
A36: COMPOUNDEYES | E36: C
A37: SNOWCLOAK | E37: C
A38: MOLDBREAKER | E38: C
A39: TINTEDLENS | D39: B
A40: FILTER | D40: B
...

Sheet Rune Options
A1: Completely Fine | B1: Redundant - Completely Fine | C1: VLOOKUP Completely Fine | D1: Comments | F1: Fine for the most part | G1: Redundant - Fine for the most part | H1: VLOOKUP Fine for the most part | I1: Comments | K1: Maybe but probably not | L1: Redundant - Maybe but probably not | M1: VLOOKUP Maybe but probably not | N1: Comments | P1: Doesn't Matter | R1: VLOOKUP Maybe but probably not | S1: Comments
A2: Battle Armor | B2: Shell Armor | C2: =VLOOKUP(A2,'Rune Listing'!$C:$C,1,FALSE) -> Battle Armor | F2: Magnet Pull | H2: =VLOOKUP(F2,'Rune Listing'!$C:$C,1,FALSE) -> #N/A | K2: Punk Rock | M2: =VLOOKUP(K2,'Rune Listing'!$C:$C,1,FALSE) -> #N/A | N2: Busted, no | P2: Stench | Q2: ??? | R2: =VLOOKUP(P2,'Rune Listing'!$C:$C,1,FALSE) -> #N/A | Y2: Dry Skin
A3: Damp | C3: =VLOOKUP(A3,'Rune Listing'!$C:$C,1,FALSE) -> #N/A | D3: Bad Ability | F3: Skill Link | H3: =VLOOKUP(F3,'Rune Listing'!$C:$C,1,FALSE) -> #N/A | I3: Lucky Dice exists and is quite good | K3: Cloud Nine | L3: Air Lock | M3: =VLOOKUP(K3,'Rune Listing'!$C:$C,1,FALSE) -> #N/A | N3: ??? | P3: Rough Skin | Q3: Iron Barbs | R3: =VLOOKUP(P3,'Rune Listing'!$C:$C,1,FALSE) -> #N/A | S3: Rocky Helmet better | U3: Dem Sanctioned Choices | Y3: Queenly Majesty
A4: Sand Veil | C4: =VLOOKUP(A4,'Rune Listing'!$C:$C,1,FALSE) -> Sand Veil | F4: Solar Power | H4: =VLOOKUP(F4,'Rune Listing'!$C:$C,1,FALSE) -> #N/A | K4: Shadow Tag | M4: =VLOOKUP(K4,'Rune Listing'!$C:$C,1,FALSE) -> #N/A | P4: Sticky Hold | Q4: Can't lose your held item | R4: =VLOOKUP(P4,'Rune Listing'!$C:$C,1,FALSE) -> #N/A | Y4: Drizzle
A5: Static | C5: =VLOOKUP(A5,'Rune Listing'!$C:$C,1,FALSE) -> Static | F5: Unaware | H5: =VLOOKUP(F5,'Rune Listing'!$C:$C,1,FALSE) -> #N/A | K5: Effect Spore | M5: =VLOOKUP(K5,'Rune Listing'!$C:$C,1,FALSE) -> #N/A | N5: Kinda good | P5: Forecast | Q5: Form specific | R5: =VLOOKUP(P5,'Rune Listing'!$C:$C,1,FALSE) -> #N/A | Y5: Speed Boost
A6: Oblivious | C6: =VLOOKUP(A6,'Rune Listing'!$C:$C,1,FALSE) -> #N/A | D6: Bad Ability | F6: Tinted Lens | H6: =VLOOKUP(F6,'Rune Listing'!$C:$C,1,FALSE) -> #N/A | K6: Trace | M6: =VLOOKUP(K6,'Rune Listing'!$C:$C,1,FALSE) -> #N/A | P6: Rock Head | Q6: Battle Armor exists and is better | R6: =VLOOKUP(P6,'Rune Listing'!$C:$C,1,FALSE) -> #N/A | Y6: Flash Fire
A7: Compound Eyes | C7: =VLOOKUP(A7,'Rune Listing'!$C:$C,1,FALSE) -> Compound Eyes | F7: Filter | G7: Solid Rock | H7: =VLOOKUP(F7,'Rune Listing'!$C:$C,1,FALSE) -> #N/A | K7: Guts | L7: Poison Heal | M7: =VLOOKUP(K7,'Rune Listing'!$C:$C,1,FALSE) -> #N/A | N7: Can't hold flame orb or toxic orb so pointless | P7: Gluttony | Q7: Can't hold berries and runes | R7: =VLOOKUP(P7,'Rune Listing'!$C:$C,1,FALSE) -> #N/A | Y7: Light Aura
A8: Limber | C8: =VLOOKUP(A8,'Rune Listing'!$C:$C,1,FALSE) -> #N/A | F8: Mummy | H8: =VLOOKUP(F8,'Rune Listing'!$C:$C,1,FALSE) -> #N/A | K8: Arena Trap | M8: =VLOOKUP(K8,'Rune Listing'!$C:$C,1,FALSE) -> Arena Trap | N8: Kinda good | P8: Symbiosis | Q8: Can't take over an ally's held item. | R8: =VLOOKUP(P8,'Rune Listing'!$C:$C,1,FALSE) -> #N/A | Y8: Opaqueness
A9: Insomnia | B9: Vital Spirit | C9: =VLOOKUP(A9,'Rune Listing'!$C:$C,1,FALSE) -> #N/A | D9: Redundant | F9: Gooey | G9: Tangling Hair | H9: =VLOOKUP(F9,'Rune Listing'!$C:$C,1,FALSE) -> Gooey | K9: Quick Feet | M9: =VLOOKUP(K9,'Rune Listing'!$C:$C,1,FALSE) -> #N/A | P9: Unburden | Q9: Can't lose your held item | R9: =VLOOKUP(P9,'Rune Listing'!$C:$C,1,FALSE) -> #N/A | Y9: Gale Wings
A10: Color Change | C10: =VLOOKUP(A10,'Rune Listing'!$C:$C,1,FALSE) -> #N/A | F10: Intuition | H10: =VLOOKUP(F10,'Rune Listing'!$C:$C,1,FALSE) -> #N/A | K10: Technician | M10: =VLOOKUP(K10,'Rune Listing'!$C:$C,1,FALSE) -> #N/A | N10: Busted, no | P10: Klutz | Q10: Can't use items | R10: =VLOOKUP(P10,'Rune Listing'!$C:$C,1,FALSE) -> #N/A | Y10: Arsonist
A11: Shield Dust | C11: =VLOOKUP(A11,'Rune Listing'!$C:$C,1,FALSE) -> Shield Dust | F11: Prism Armor | H11: =VLOOKUP(F11,'Rune Listing'!$C:$C,1,FALSE) -> Prism Armor | K11: Toxic Boost | L11: Flare Boost | M11: =VLOOKUP(K11,'Rune Listing'!$C:$C,1,FALSE) -> #N/A | N11: Can't hold flame orb or toxic orb so pointless | P11: Pickpocket | Q11: Can't steal | R11: =VLOOKUP(P11,'Rune Listing'!$C:$C,1,FALSE) -> #N/A | Y11: Electric Surge
A12: Own Tempo | C12: =VLOOKUP(A12,'Rune Listing'!$C:$C,1,FALSE) -> #N/A | F12: Inner Focus | H12: =VLOOKUP(F12,'Rune Listing'!$C:$C,1,FALSE) -> Inner Focus | K12: Regenerator | M12: =VLOOKUP(K12,'Rune Listing'!$C:$C,1,FALSE) -> #N/A | N12: Kinda good | P12: Super Luck | Q12: ??? | R12: =VLOOKUP(P12,'Rune Listing'!$C:$C,1,FALSE) -> #N/A | Y12: Contrary
A13: Suction Cups | C13: =VLOOKUP(A13,'Rune Listing'!$C:$C,1,FALSE) -> #N/A | F13: Hyper Cutter | H13: =VLOOKUP(F13,'Rune Listing'!$C:$C,1,FALSE) -> #N/A | K13: Wonder Skin | M13: =VLOOKUP(K13,'Rune Listing'!$C:$C,1,FALSE) -> #N/A | N13: Kinda good | P13: Anticipation | Q13: Bad Ability | R13: =VLOOKUP(P13,'Rune Listing'!$C:$C,1,FALSE) -> #N/A | Y13: Sturdy
A14: Synchronize | C14: =VLOOKUP(A14,'Rune Listing'!$C:$C,1,FALSE) -> Synchronize | K14: Moxie | M14: =VLOOKUP(K14,'Rune Listing'!$C:$C,1,FALSE) -> #N/A | N14: Busted, no | P14: Multitype | Q14: Form specific | R14: =VLOOKUP(P14,'Rune Listing'!$C:$C,1,FALSE) -> #N/A | Y14: Huge Power
A15: Natural Cure | C15: =VLOOKUP(A15,'Rune Listing'!$C:$C,1,FALSE) -> Natural Cure | K15: Requiem | M15: =VLOOKUP(K15,'Rune Listing'!$C:$C,1,FALSE) -> #N/A | P15: Light Metal | Q15: Weight plays are kinda niche | R15: =VLOOKUP(P15,'Rune Listing'!$C:$C,1,FALSE) -> #N/A | Y15: Volt Absorb
A16: Illuminate | C16: =VLOOKUP(A16,'Rune Listing'!$C:$C,1,FALSE) -> #N/A | K16: Sand Force | M16: =VLOOKUP(K16,'Rune Listing'!$C:$C,1,FALSE) -> #N/A | P16: Harvest | Q16: Can't hold berries and runes | R16: =VLOOKUP(P16,'Rune Listing'!$C:$C,1,FALSE) -> #N/A | Y16: Water Absorb
A17: Poison Point | C17: =VLOOKUP(A17,'Rune Listing'!$C:$C,1,FALSE) -> Poison Point | K17: Aroma Veil | M17: =VLOOKUP(K17,'Rune Listing'!$C:$C,1,FALSE) -> #N/A | N17: Situational | P17: Overcoat | Q17: ??? | R17: =VLOOKUP(P17,'Rune Listing'!$C:$C,1,FALSE) -> #N/A | S17: Bad Ability | Y17: Immunity
A18: Magma Armor | C18: =VLOOKUP(A18,'Rune Listing'!$C:$C,1,FALSE) -> #N/A | K18: Strong Jaw | M18: =VLOOKUP(K18,'Rune Listing'!$C:$C,1,FALSE) -> #N/A | N18: Busted, no | P18: Long Reach | Q18: ??? | R18: =VLOOKUP(P18,'Rune Listing'!$C:$C,1,FALSE) -> #N/A | Y18: Lightning Rod
A19: Water Veil | C19: =VLOOKUP(A19,'Rune Listing'!$C:$C,1,FALSE) -> #N/A | K19: Attunement | M19: =VLOOKUP(K19,'Rune Listing'!$C:$C,1,FALSE) -> #N/A | N19: Special guts, no | P19: Zen Mode | Q19: Form specific | R19: =VLOOKUP(P19,'Rune Listing'!$C:$C,1,FALSE) -> #N/A | Y19: Anger Shell
A20: Rain Dish | C20: =VLOOKUP(A20,'Rune Listing'!$C:$C,1,FALSE) -> Rain Dish | K20: Mega Launcher | M20: =VLOOKUP(K20,'Rune Listing'!$C:$C,1,FALSE) -> #N/A | N20: Busted, no | P20: Stance Change | Q20: Form specific | R20: =VLOOKUP(P20,'Rune Listing'!$C:$C,1,FALSE) -> #N/A | Y20: Tropical Hide
A21: Pressure | C21: =VLOOKUP(A21,'Rune Listing'!$C:$C,1,FALSE) -> #N/A | D21: Situational | K21: Sharpness | M21: =VLOOKUP(K21,'Rune Listing'!$C:$C,1,FALSE) -> #N/A | N21: Busted, no | P21: Shields Down | Q21: Form specific | R21: =VLOOKUP(P21,'Rune Listing'!$C:$C,1,FALSE) -> #N/A | Y21: Hadron Engine
A22: Early Bird | C22: =VLOOKUP(A22,'Rune Listing'!$C:$C,1,FALSE) -> #N/A | K22: Parental Bond | M22: =VLOOKUP(K22,'Rune Listing'!$C:$C,1,FALSE) -> #N/A | N22: Busted, no | P22: Turboblaze | Q22: Mold Breaker Redundant | R22: =VLOOKUP(P22,'Rune Listing'!$C:$C,1,FALSE) -> #N/A | Y22: Affection
A23: Flame Body | C23: =VLOOKUP(A23,'Rune Listing'!$C:$C,1,FALSE) -> Flame Body | K23: Emergency Exit | M23: =VLOOKUP(K23,'Rune Listing'!$C:$C,1,FALSE) -> #N/A | P23: Teravolt | Q23: Mold Breaker Redundant | R23: =VLOOKUP(P23,'Rune Listing'!$C:$C,1,FALSE) -> #N/A | Y23: Disarray
A24: Run Away | C24: =VLOOKUP(A24,'Rune Listing'!$C:$C,1,FALSE) -> #N/A | D24: Demon Eye basically better? | K24: Merciless | M24: =VLOOKUP(K24,'Rune Listing'!$C:$C,1,FALSE) -> #N/A | N24: Kinda niche | P24: Cheek Pouch | Q24: Can't hold berries and runes | R24: =VLOOKUP(P24,'Rune Listing'!$C:$C,1,FALSE) -> #N/A | Y24: Earth Eater
A25: Keen Eye | C25: =VLOOKUP(A25,'Rune Listing'!$C:$C,1,FALSE) -> #N/A | K25: Battery | M25: =VLOOKUP(K25,'Rune Listing'!$C:$C,1,FALSE) -> #N/A | P25: Magician | Q25: Can't steal | R25: =VLOOKUP(P25,'Rune Listing'!$C:$C,1,FALSE) -> #N/A | Y25: Toxic Debris
A26: Cute Charm | C26: =VLOOKUP(A26,'Rune Listing'!$C:$C,1,FALSE) -> #N/A | D26: Bad Ability | K26: Power Spot | M26: =VLOOKUP(K26,'Rune Listing'!$C:$C,1,FALSE) -> #N/A | N26: Kinda good | P26: Schooling | Q26: Form specific | R26: =VLOOKUP(P26,'Rune Listing'!$C:$C,1,FALSE) -> #N/A | Y26: Costar
A27: Plus | C27: =VLOOKUP(A27,'Rune Listing'!$C:$C,1,FALSE) -> #N/A | D27: Situational | K27: Wandering Spirit | M27: =VLOOKUP(K27,'Rune Listing'!$C:$C,1,FALSE) -> #N/A | N27: Pointless | P27: Battle Bond | Q27: Form specific | R27: =VLOOKUP(P27,'Rune Listing'!$C:$C,1,FALSE) -> #N/A | Y27: Scorch Scale
A28: Minus | C28: =VLOOKUP(A28,'Rune Listing'!$C:$C,1,FALSE) -> #N/A | D28: Situational | K28: White Smoke | L28: Full Metal Body | M28: =VLOOKUP(K28,'Rune Listing'!$C:$C,1,FALSE) -> #N/A | N28: Redundant | P28: Power Construct | Q28: Form specific | R28: =VLOOKUP(P28,'Rune Listing'!$C:$C,1,FALSE) -> #N/A | Y28: Hivemind
A29: Shed Skin | C29: =VLOOKUP(A29,'Rune Listing'!$C:$C,1,FALSE) -> #N/A | K29: Clear Body | L29: Full Metal Body | M29: =VLOOKUP(K29,'Rune Listing'!$C:$C,1,FALSE) -> Clear Body | N29: Redundant | P29: RKS System | Q29: Form specific | R29: =VLOOKUP(P29,'Rune Listing'!$C:$C,1,FALSE) -> #N/A | Y29: Rocky Payload
A30: Vital Spirit | C30: =VLOOKUP(A30,'Rune Listing'!$C:$C,1,FALSE) -> Vital Spirit | K30: Cannon Fire | M30: =VLOOKUP(K30,'Rune Listing'!$C:$C,1,FALSE) -> #N/A | N30: Busted, no | P30: Full Metal Body | Q30: ??? | R30: =VLOOKUP(P30,'Rune Listing'!$C:$C,1,FALSE) -> #N/A | Y30: Irredeemable
A31: Marvel Scale | C31: =VLOOKUP(A31,'Rune Listing'!$C:$C,1,FALSE) -> #N/A | K31: Icy Veins | M31: =VLOOKUP(K31,'Rune Listing'!$C:$C,1,FALSE) -> #N/A | N31: Kinda OP but no. | P31: Gorilla Tactics | Q31: ??? | R31: =VLOOKUP(P31,'Rune Listing'!$C:$C,1,FALSE) -> #N/A | S31: Choice Band better | Y31: Intimidate
A32: Liquid Ooze | C32: =VLOOKUP(A32,'Rune Listing'!$C:$C,1,FALSE) -> Liquid Ooze | P32: Hunger Switch | Q32: Form specific | R32: =VLOOKUP(P32,'Rune Listing'!$C:$C,1,FALSE) -> #N/A | Y32: Anti-Gravity
A33: Tangled Feet | C33: =VLOOKUP(A33,'Rune Listing'!$C:$C,1,FALSE) -> #N/A | P33: Pure Heart | Q33: Leftovers is just better | R33: =VLOOKUP(P33,'Rune Listing'!$C:$C,1,FALSE) -> #N/A | Y33: Terrorize
A34: Rivalry | C34: =VLOOKUP(A34,'Rune Listing'!$C:$C,1,FALSE) -> Rivalry | D34: Bad Ability | Y34: Light Bulb
A35: Steadfast | C35: =VLOOKUP(A35,'Rune Listing'!$C:$C,1,FALSE) -> #N/A | Y35: Comet Storm
A36: Snow Cloak | C36: =VLOOKUP(A36,'Rune Listing'!$C:$C,1,FALSE) -> Snow Cloak | Y36: Wonder Guard
A37: Iron Fist | C37: =VLOOKUP(A37,'Rune Listing'!$C:$C,1,FALSE) -> #N/A | D37: Tough Claws is better | Y37: Nebula Cloud
A38: Hydration | C38: =VLOOKUP(A38,'Rune Listing'!$C:$C,1,FALSE) -> #N/A | Y38: Spellcaster
A39: Normalize | C39: =VLOOKUP(A39,'Rune Listing'!$C:$C,1,FALSE) -> #N/A | D39: No, Skill Swap shenanigans | Y39: Virtuoso
A40: Sniper | C40: =VLOOKUP(A40,'Rune Listing'!$C:$C,1,FALSE) -> Sniper | Y40: Astral Majesty
...

Sheet Raw Data
A1: Ability Listing | B1: NO | C1: Doesn't Matter | D1: Maybe but probably not | E1: Fine for the most part | F1: Completely Fine | Q1: NO | R1: Doesn't Matter | S1: Maybe but probably not | T1: Fine for the most part | U1: Completely Fine
A2: LEVITATE | B2: =IFERROR(IF(VLOOKUP($A2,Q$2:Q$175,1,FALSE)=$A2,"S",""),"") -> S | C2: =IFERROR(IF(VLOOKUP($A2,R$2:R$175,1,FALSE)=$A2,"D",""),"") | D2: =IFERROR(IF(VLOOKUP($A2,S$2:S$175,1,FALSE)=$A2,"A",""),"") | E2: =IFERROR(IF(VLOOKUP($A2,T$2:T$175,1,FALSE)=$A2,"B",""),"") | F2: =IFERROR(IF(VLOOKUP($A2,U$2:U$175,1,FALSE)=$A2,"C",""),"") | G2: =COUNTBLANK(B2:F2) -> 4 | Q2: DRYSKIN | R2: STENCH | S2: PUNKROCK | T2: MAGNETPULL | U2: BATTLEARMOR
A3: INTIMIDATE | B3: =IFERROR(IF(VLOOKUP($A3,Q$2:Q$175,1,FALSE)=$A3,"S",""),"") -> S | C3: =IFERROR(IF(VLOOKUP($A3,R$2:R$175,1,FALSE)=$A3,"D",""),"") | D3: =IFERROR(IF(VLOOKUP($A3,S$2:S$175,1,FALSE)=$A3,"A",""),"") | E3: =IFERROR(IF(VLOOKUP($A3,T$2:T$175,1,FALSE)=$A3,"B",""),"") | F3: =IFERROR(IF(VLOOKUP($A3,U$2:U$175,1,FALSE)=$A3,"C",""),"") | G3: =COUNTBLANK(B3:F3) -> 4 | Q3: QUEENLYMAJESTY | R3: ROUGHSKIN | S3: CLOUDNINE | T3: SKILLLINK | U3: DAMP
A4: STATIC | B4: =IFERROR(IF(VLOOKUP($A4,Q$2:Q$175,1,FALSE)=$A4,"S",""),"") | C4: =IFERROR(IF(VLOOKUP($A4,R$2:R$175,1,FALSE)=$A4,"D",""),"") | D4: =IFERROR(IF(VLOOKUP($A4,S$2:S$175,1,FALSE)=$A4,"A",""),"") | E4: =IFERROR(IF(VLOOKUP($A4,T$2:T$175,1,FALSE)=$A4,"B",""),"") | F4: =IFERROR(IF(VLOOKUP($A4,U$2:U$175,1,FALSE)=$A4,"C",""),"") -> C | G4: =COUNTBLANK(B4:F4) -> 4 | Q4: DRIZZLE | R4: STICKYHOLD | S4: SHADOWTAG | T4: SOLARPOWER | U4: SANDVEIL
A5: MOXIE | B5: =IFERROR(IF(VLOOKUP($A5,Q$2:Q$175,1,FALSE)=$A5,"S",""),"") | C5: =IFERROR(IF(VLOOKUP($A5,R$2:R$175,1,FALSE)=$A5,"D",""),"") | D5: =IFERROR(IF(VLOOKUP($A5,S$2:S$175,1,FALSE)=$A5,"A",""),"") -> A | E5: =IFERROR(IF(VLOOKUP($A5,T$2:T$175,1,FALSE)=$A5,"B",""),"") | F5: =IFERROR(IF(VLOOKUP($A5,U$2:U$175,1,FALSE)=$A5,"C",""),"") | G5: =COUNTBLANK(B5:F5) -> 4 | Q5: SPEEDBOOST | R5: FORECAST | S5: EFFECTSPORE | T5: UNAWARE | U5: STATIC
A6: TELEPATHY | B6: =IFERROR(IF(VLOOKUP($A6,Q$2:Q$175,1,FALSE)=$A6,"S",""),"") | C6: =IFERROR(IF(VLOOKUP($A6,R$2:R$175,1,FALSE)=$A6,"D",""),"") | D6: =IFERROR(IF(VLOOKUP($A6,S$2:S$175,1,FALSE)=$A6,"A",""),"") | E6: =IFERROR(IF(VLOOKUP($A6,T$2:T$175,1,FALSE)=$A6,"B",""),"") | F6: =IFERROR(IF(VLOOKUP($A6,U$2:U$175,1,FALSE)=$A6,"C",""),"") -> C | G6: =COUNTBLANK(B6:F6) -> 4 | Q6: FLASHFIRE | R6: ROCKHEAD | S6: TRACE | T6: TINTEDLENS | U6: OBLIVIOUS
A7: FLAMEBODY | B7: =IFERROR(IF(VLOOKUP($A7,Q$2:Q$175,1,FALSE)=$A7,"S",""),"") | C7: =IFERROR(IF(VLOOKUP($A7,R$2:R$175,1,FALSE)=$A7,"D",""),"") | D7: =IFERROR(IF(VLOOKUP($A7,S$2:S$175,1,FALSE)=$A7,"A",""),"") | E7: =IFERROR(IF(VLOOKUP($A7,T$2:T$175,1,FALSE)=$A7,"B",""),"") | F7: =IFERROR(IF(VLOOKUP($A7,U$2:U$175,1,FALSE)=$A7,"C",""),"") -> C | G7: =COUNTBLANK(B7:F7) -> 4 | Q7: LIGHTAURA | R7: GLUTTONY | S7: GUTS | T7: FILTER | U7: COMPOUNDEYES
A8: INFILTRATOR | B8: =IFERROR(IF(VLOOKUP($A8,Q$2:Q$175,1,FALSE)=$A8,"S",""),"") | C8: =IFERROR(IF(VLOOKUP($A8,R$2:R$175,1,FALSE)=$A8,"D",""),"") | D8: =IFERROR(IF(VLOOKUP($A8,S$2:S$175,1,FALSE)=$A8,"A",""),"") | E8: =IFERROR(IF(VLOOKUP($A8,T$2:T$175,1,FALSE)=$A8,"B",""),"") | F8: =IFERROR(IF(VLOOKUP($A8,U$2:U$175,1,FALSE)=$A8,"C",""),"") -> C | G8: =COUNTBLANK(B8:F8) -> 4 | Q8: OPAQUENESS | R8: SYMBIOSIS | S8: ARENATRAP | T8: MUMMY | U8: LIMBER
A9: RAINDISH | B9: =IFERROR(IF(VLOOKUP($A9,Q$2:Q$175,1,FALSE)=$A9,"S",""),"") | C9: =IFERROR(IF(VLOOKUP($A9,R$2:R$175,1,FALSE)=$A9,"D",""),"") | D9: =IFERROR(IF(VLOOKUP($A9,S$2:S$175,1,FALSE)=$A9,"A",""),"") | E9: =IFERROR(IF(VLOOKUP($A9,T$2:T$175,1,FALSE)=$A9,"B",""),"") | F9: =IFERROR(IF(VLOOKUP($A9,U$2:U$175,1,FALSE)=$A9,"C",""),"") -> C | G9: =COUNTBLANK(B9:F9) -> 4 | Q9: GALEWINGS | R9: UNBURDEN | S9: QUICKFEET | T9: GOOEY | U9: INSOMNIA
A10: SOLIDROCK | B10: =IFERROR(IF(VLOOKUP($A10,Q$2:Q$175,1,FALSE)=$A10,"S",""),"") | C10: =IFERROR(IF(VLOOKUP($A10,R$2:R$175,1,FALSE)=$A10,"D",""),"") | D10: =IFERROR(IF(VLOOKUP($A10,S$2:S$175,1,FALSE)=$A10,"A",""),"") -> A | E10: =IFERROR(IF(VLOOKUP($A10,T$2:T$175,1,FALSE)=$A10,"B",""),"") | F10: =IFERROR(IF(VLOOKUP($A10,U$2:U$175,1,FALSE)=$A10,"C",""),"") | G10: =COUNTBLANK(B10:F10) -> 4 | Q10: ARSONIST | R10: KLUTZ | S10: TECHNICIAN | T10: INTUITION | U10: COLORCHANGE
A11: RECKLESS | B11: =IFERROR(IF(VLOOKUP($A11,Q$2:Q$175,1,FALSE)=$A11,"S",""),"") | C11: =IFERROR(IF(VLOOKUP($A11,R$2:R$175,1,FALSE)=$A11,"D",""),"") | D11: =IFERROR(IF(VLOOKUP($A11,S$2:S$175,1,FALSE)=$A11,"A",""),"") | E11: =IFERROR(IF(VLOOKUP($A11,T$2:T$175,1,FALSE)=$A11,"B",""),"") | F11: =IFERROR(IF(VLOOKUP($A11,U$2:U$175,1,FALSE)=$A11,"C",""),"") -> C | G11: =COUNTBLANK(B11:F11) -> 4 | Q11: ELECTRICSURGE | R11: PICKPOCKET | S11: TOXICBOOST | T11: PRISMARMOR | U11: SHIELDDUST
A12: WATERABSORB | B12: =IFERROR(IF(VLOOKUP($A12,Q$2:Q$175,1,FALSE)=$A12,"S",""),"") -> S | C12: =IFERROR(IF(VLOOKUP($A12,R$2:R$175,1,FALSE)=$A12,"D",""),"") | D12: =IFERROR(IF(VLOOKUP($A12,S$2:S$175,1,FALSE)=$A12,"A",""),"") | E12: =IFERROR(IF(VLOOKUP($A12,T$2:T$175,1,FALSE)=$A12,"B",""),"") | F12: =IFERROR(IF(VLOOKUP($A12,U$2:U$175,1,FALSE)=$A12,"C",""),"") | G12: =COUNTBLANK(B12:F12) -> 4 | Q12: CONTRARY | R12: SUPERLUCK | S12: REGENERATOR | T12: INNERFOCUS | U12: OWNTEMPO
A13: PRANKSTER | B13: =IFERROR(IF(VLOOKUP($A13,Q$2:Q$175,1,FALSE)=$A13,"S",""),"") -> S | C13: =IFERROR(IF(VLOOKUP($A13,R$2:R$175,1,FALSE)=$A13,"D",""),"") | D13: =IFERROR(IF(VLOOKUP($A13,S$2:S$175,1,FALSE)=$A13,"A",""),"") | E13: =IFERROR(IF(VLOOKUP($A13,T$2:T$175,1,FALSE)=$A13,"B",""),"") | F13: =IFERROR(IF(VLOOKUP($A13,U$2:U$175,1,FALSE)=$A13,"C",""),"") | G13: =COUNTBLANK(B13:F13) -> 4 | Q13: STURDY | R13: ANTICIPATION | S13: WONDERSKIN | T13: HYPERCUTTER | U13: SUCTIONCUPS
A14: DRYSKIN | B14: =IFERROR(IF(VLOOKUP($A14,Q$2:Q$175,1,FALSE)=$A14,"S",""),"") -> S | C14: =IFERROR(IF(VLOOKUP($A14,R$2:R$175,1,FALSE)=$A14,"D",""),"") | D14: =IFERROR(IF(VLOOKUP($A14,S$2:S$175,1,FALSE)=$A14,"A",""),"") | E14: =IFERROR(IF(VLOOKUP($A14,T$2:T$175,1,FALSE)=$A14,"B",""),"") | F14: =IFERROR(IF(VLOOKUP($A14,U$2:U$175,1,FALSE)=$A14,"C",""),"") | G14: =COUNTBLANK(B14:F14) -> 4 | Q14: HUGEPOWER | R14: MULTITYPE | S14: MOXIE | U14: SYNCHRONIZE
A15: OBLIVIOUS | B15: =IFERROR(IF(VLOOKUP($A15,Q$2:Q$175,1,FALSE)=$A15,"S",""),"") | C15: =IFERROR(IF(VLOOKUP($A15,R$2:R$175,1,FALSE)=$A15,"D",""),"") | D15: =IFERROR(IF(VLOOKUP($A15,S$2:S$175,1,FALSE)=$A15,"A",""),"") | E15: =IFERROR(IF(VLOOKUP($A15,T$2:T$175,1,FALSE)=$A15,"B",""),"") | F15: =IFERROR(IF(VLOOKUP($A15,U$2:U$175,1,FALSE)=$A15,"C",""),"") -> C | G15: =COUNTBLANK(B15:F15) -> 4 | Q15: VOLTABSORB | R15: LIGHTMETAL | S15: REQUIEM | U15: NATURALCURE
A16: SHEERFORCE | B16: =IFERROR(IF(VLOOKUP($A16,Q$2:Q$175,1,FALSE)=$A16,"S",""),"") | C16: =IFERROR(IF(VLOOKUP($A16,R$2:R$175,1,FALSE)=$A16,"D",""),"") | D16: =IFERROR(IF(VLOOKUP($A16,S$2:S$175,1,FALSE)=$A16,"A",""),"") | E16: =IFERROR(IF(VLOOKUP($A16,T$2:T$175,1,FALSE)=$A16,"B",""),"") | F16: =IFERROR(IF(VLOOKUP($A16,U$2:U$175,1,FALSE)=$A16,"C",""),"") -> C | G16: =COUNTBLANK(B16:F16) -> 4 | Q16: WATERABSORB | R16: HARVEST | S16: SANDFORCE | U16: ILLUMINATE
A17: DEFIANT | B17: =IFERROR(IF(VLOOKUP($A17,Q$2:Q$175,1,FALSE)=$A17,"S",""),"") -> S | C17: =IFERROR(IF(VLOOKUP($A17,R$2:R$175,1,FALSE)=$A17,"D",""),"") | D17: =IFERROR(IF(VLOOKUP($A17,S$2:S$175,1,FALSE)=$A17,"A",""),"") | E17: =IFERROR(IF(VLOOKUP($A17,T$2:T$175,1,FALSE)=$A17,"B",""),"") | F17: =IFERROR(IF(VLOOKUP($A17,U$2:U$175,1,FALSE)=$A17,"C",""),"") | G17: =COUNTBLANK(B17:F17) -> 4 | Q17: IMMUNITY | R17: OVERCOAT | S17: AROMAVEIL | U17: POISONPOINT
A18: OVERCOAT | B18: =IFERROR(IF(VLOOKUP($A18,Q$2:Q$175,1,FALSE)=$A18,"S",""),"") | C18: =IFERROR(IF(VLOOKUP($A18,R$2:R$175,1,FALSE)=$A18,"D",""),"") -> D | D18: =IFERROR(IF(VLOOKUP($A18,S$2:S$175,1,FALSE)=$A18,"A",""),"") | E18: =IFERROR(IF(VLOOKUP($A18,T$2:T$175,1,FALSE)=$A18,"B",""),"") | F18: =IFERROR(IF(VLOOKUP($A18,U$2:U$175,1,FALSE)=$A18,"C",""),"") | G18: =COUNTBLANK(B18:F18) -> 4 | Q18: LIGHTNINGROD | R18: LONGREACH | S18: STRONGJAW | U18: MAGMAARMOR
A19: SHIELDDUST | B19: =IFERROR(IF(VLOOKUP($A19,Q$2:Q$175,1,FALSE)=$A19,"S",""),"") | C19: =IFERROR(IF(VLOOKUP($A19,R$2:R$175,1,FALSE)=$A19,"D",""),"") | D19: =IFERROR(IF(VLOOKUP($A19,S$2:S$175,1,FALSE)=$A19,"A",""),"") | E19: =IFERROR(IF(VLOOKUP($A19,T$2:T$175,1,FALSE)=$A19,"B",""),"") | F19: =IFERROR(IF(VLOOKUP($A19,U$2:U$175,1,FALSE)=$A19,"C",""),"") -> C | G19: =COUNTBLANK(B19:F19) -> 4 | Q19: ANGERSHELL | R19: ZENMODE | S19: ATTUNEMENT | U19: WATERVEIL
A20: THICKFAT | B20: =IFERROR(IF(VLOOKUP($A20,Q$2:Q$175,1,FALSE)=$A20,"S",""),"") -> S | C20: =IFERROR(IF(VLOOKUP($A20,R$2:R$175,1,FALSE)=$A20,"D",""),"") | D20: =IFERROR(IF(VLOOKUP($A20,S$2:S$175,1,FALSE)=$A20,"A",""),"") | E20: =IFERROR(IF(VLOOKUP($A20,T$2:T$175,1,FALSE)=$A20,"B",""),"") | F20: =IFERROR(IF(VLOOKUP($A20,U$2:U$175,1,FALSE)=$A20,"C",""),"") | G20: =COUNTBLANK(B20:F20) -> 4 | Q20: TROPICALHIDE | R20: STANCECHANGE | S20: MEGALAUNCHER | U20: RAINDISH
A21: POISONTOUCH | B21: =IFERROR(IF(VLOOKUP($A21,Q$2:Q$175,1,FALSE)=$A21,"S",""),"") | C21: =IFERROR(IF(VLOOKUP($A21,R$2:R$175,1,FALSE)=$A21,"D",""),"") | D21: =IFERROR(IF(VLOOKUP($A21,S$2:S$175,1,FALSE)=$A21,"A",""),"") | E21: =IFERROR(IF(VLOOKUP($A21,T$2:T$175,1,FALSE)=$A21,"B",""),"") | F21: =IFERROR(IF(VLOOKUP($A21,U$2:U$175,1,FALSE)=$A21,"C",""),"") -> C | G21: =COUNTBLANK(B21:F21) -> 4 | Q21: HADRONENGINE | R21: SHIELDSDOWN | S21: SHARPNESS | U21: PRESSURE
A22: ANALYTIC | B22: =IFERROR(IF(VLOOKUP($A22,Q$2:Q$175,1,FALSE)=$A22,"S",""),"") | C22: =IFERROR(IF(VLOOKUP($A22,R$2:R$175,1,FALSE)=$A22,"D",""),"") | D22: =IFERROR(IF(VLOOKUP($A22,S$2:S$175,1,FALSE)=$A22,"A",""),"") | E22: =IFERROR(IF(VLOOKUP($A22,T$2:T$175,1,FALSE)=$A22,"B",""),"") | F22: =IFERROR(IF(VLOOKUP($A22,U$2:U$175,1,FALSE)=$A22,"C",""),"") -> C | G22: =COUNTBLANK(B22:F22) -> 4 | Q22: AFFECTION | R22: TURBOBLAZE | S22: PARENTALBOND | U22: EARLYBIRD
A23: STRONGJAW | B23: =IFERROR(IF(VLOOKUP($A23,Q$2:Q$175,1,FALSE)=$A23,"S",""),"") | C23: =IFERROR(IF(VLOOKUP($A23,R$2:R$175,1,FALSE)=$A23,"D",""),"") | D23: =IFERROR(IF(VLOOKUP($A23,S$2:S$175,1,FALSE)=$A23,"A",""),"") -> A | E23: =IFERROR(IF(VLOOKUP($A23,T$2:T$175,1,FALSE)=$A23,"B",""),"") | F23: =IFERROR(IF(VLOOKUP($A23,U$2:U$175,1,FALSE)=$A23,"C",""),"") | G23: =COUNTBLANK(B23:F23) -> 4 | Q23: DISARRAY | R23: TERAVOLT | S23: EMERGENCYEXIT | U23: FLAMEBODY
A24: ROUGHSKIN | B24: =IFERROR(IF(VLOOKUP($A24,Q$2:Q$175,1,FALSE)=$A24,"S",""),"") | C24: =IFERROR(IF(VLOOKUP($A24,R$2:R$175,1,FALSE)=$A24,"D",""),"") -> D | D24: =IFERROR(IF(VLOOKUP($A24,S$2:S$175,1,FALSE)=$A24,"A",""),"") | E24: =IFERROR(IF(VLOOKUP($A24,T$2:T$175,1,FALSE)=$A24,"B",""),"") | F24: =IFERROR(IF(VLOOKUP($A24,U$2:U$175,1,FALSE)=$A24,"C",""),"") | G24: =COUNTBLANK(B24:F24) -> 4 | Q24: EARTHEATER | R24: CHEEKPOUCH | S24: MERCILESS | U24: RUNAWAY
A25: SWARM | B25: =IFERROR(IF(VLOOKUP($A25,Q$2:Q$175,1,FALSE)=$A25,"S",""),"") -> S | C25: =IFERROR(IF(VLOOKUP($A25,R$2:R$175,1,FALSE)=$A25,"D",""),"") | D25: =IFERROR(IF(VLOOKUP($A25,S$2:S$175,1,FALSE)=$A25,"A",""),"") | E25: =IFERROR(IF(VLOOKUP($A25,T$2:T$175,1,FALSE)=$A25,"B",""),"") | F25: =IFERROR(IF(VLOOKUP($A25,U$2:U$175,1,FALSE)=$A25,"C",""),"") | G25: =COUNTBLANK(B25:F25) -> 4 | Q25: TOXICDEBRIS | R25: MAGICIAN | S25: BATTERY | U25: KEENEYE
... A33: DAZZLING | B33: =IFERROR(IF(VLOOKUP($A33,Q$2:Q$175,1,FALSE)=$A33,"S",""),"") -> S | C33: =IFERROR(IF(VLOOKUP($A33,R$2:R$175,1,FALSE)=$A33,"D",""),"") | D33: =IFERROR(IF(VLOOKUP($A33,S$2:S$175,1,FALSE)=$A33,"A",""),"") | E33: =IFERROR(IF(VLOOKUP($A33,T$2:T$175,1,FALSE)=$A33,"B",""),"") | F33: =IFERROR(IF(VLOOKUP($A33,U$2:U$175,1,FALSE)=$A33,"C",""),"") | G33: =COUNTBLANK(B33:F33) -> 4 | Q33: TERRORIZE | R33: IRONBARBS | S33: TANGLINGHAIR | U33: TANGLEDFEET
A34: STURDY | B34: =IFERROR(IF(VLOOKUP($A34,Q$2:Q$175,1,FALSE)=$A34,"S",""),"") -> S | C34: =IFERROR(IF(VLOOKUP($A34,R$2:R$175,1,FALSE)=$A34,"D",""),"") | D34: =IFERROR(IF(VLOOKUP($A34,S$2:S$175,1,FALSE)=$A34,"A",""),"") | E34: =IFERROR(IF(VLOOKUP($A34,T$2:T$175,1,FALSE)=$A34,"B",""),"") | F34: =IFERROR(IF(VLOOKUP($A34,U$2:U$175,1,FALSE)=$A34,"C",""),"") | G34: =COUNTBLANK(B34:F34) -> 4 | Q34: LIGHTBULB | S34: AIRLOCK | U34: RIVALRY
A35: CLOUDNINE | B35: =IFERROR(IF(VLOOKUP($A35,Q$2:Q$175,1,FALSE)=$A35,"S",""),"") | C35: =IFERROR(IF(VLOOKUP($A35,R$2:R$175,1,FALSE)=$A35,"D",""),"") | D35: =IFERROR(IF(VLOOKUP($A35,S$2:S$175,1,FALSE)=$A35,"A",""),"") -> A | E35: =IFERROR(IF(VLOOKUP($A35,T$2:T$175,1,FALSE)=$A35,"B",""),"") | F35: =IFERROR(IF(VLOOKUP($A35,U$2:U$175,1,FALSE)=$A35,"C",""),"") | G35: =COUNTBLANK(B35:F35) -> 4 | Q35: COMETSTORM | S35: POISONHEAL | U35: STEADFAST
A36: COMPOUNDEYES | B36: =IFERROR(IF(VLOOKUP($A36,Q$2:Q$175,1,FALSE)=$A36,"S",""),"") | C36: =IFERROR(IF(VLOOKUP($A36,R$2:R$175,1,FALSE)=$A36,"D",""),"") | D36: =IFERROR(IF(VLOOKUP($A36,S$2:S$175,1,FALSE)=$A36,"A",""),"") | E36: =IFERROR(IF(VLOOKUP($A36,T$2:T$175,1,FALSE)=$A36,"B",""),"") | F36: =IFERROR(IF(VLOOKUP($A36,U$2:U$175,1,FALSE)=$A36,"C",""),"") -> C | G36: =COUNTBLANK(B36:F36) -> 4 | Q36: WONDERGUARD | S36: FLAREBOOST | U36: SNOWCLOAK
A37: SNOWCLOAK | B37: =IFERROR(IF(VLOOKUP($A37,Q$2:Q$175,1,FALSE)=$A37,"S",""),"") | C37: =IFERROR(IF(VLOOKUP($A37,R$2:R$175,1,FALSE)=$A37,"D",""),"") | D37: =IFERROR(IF(VLOOKUP($A37,S$2:S$175,1,FALSE)=$A37,"A",""),"") | E37: =IFERROR(IF(VLOOKUP($A37,T$2:T$175,1,FALSE)=$A37,"B",""),"") | F37: =IFERROR(IF(VLOOKUP($A37,U$2:U$175,1,FALSE)=$A37,"C",""),"") -> C | G37: =COUNTBLANK(B37:F37) -> 4 | Q37: NEBULACLOUD | S37: FULLMETALBODY | U37: IRONFIST
A38: MOLDBREAKER | B38: =IFERROR(IF(VLOOKUP($A38,Q$2:Q$175,1,FALSE)=$A38,"S",""),"") | C38: =IFERROR(IF(VLOOKUP($A38,R$2:R$175,1,FALSE)=$A38,"D",""),"") | D38: =IFERROR(IF(VLOOKUP($A38,S$2:S$175,1,FALSE)=$A38,"A",""),"") | E38: =IFERROR(IF(VLOOKUP($A38,T$2:T$175,1,FALSE)=$A38,"B",""),"") | F38: =IFERROR(IF(VLOOKUP($A38,U$2:U$175,1,FALSE)=$A38,"C",""),"") -> C | G38: =COUNTBLANK(B38:F38) -> 4 | Q38: SPELLCASTER | U38: HYDRATION
A39: TINTEDLENS | B39: =IFERROR(IF(VLOOKUP($A39,Q$2:Q$175,1,FALSE)=$A39,"S",""),"") | C39: =IFERROR(IF(VLOOKUP($A39,R$2:R$175,1,FALSE)=$A39,"D",""),"") | D39: =IFERROR(IF(VLOOKUP($A39,S$2:S$175,1,FALSE)=$A39,"A",""),"") | E39: =IFERROR(IF(VLOOKUP($A39,T$2:T$175,1,FALSE)=$A39,"B",""),"") -> B | F39: =IFERROR(IF(VLOOKUP($A39,U$2:U$175,1,FALSE)=$A39,"C",""),"") | G39: =COUNTBLANK(B39:F39) -> 4 | Q39: VIRTUOSO | U39: NORMALIZE
A40: FILTER | B40: =IFERROR(IF(VLOOKUP($A40,Q$2:Q$175,1,FALSE)=$A40,"S",""),"") | C40: =IFERROR(IF(VLOOKUP($A40,R$2:R$175,1,FALSE)=$A40,"D",""),"") | D40: =IFERROR(IF(VLOOKUP($A40,S$2:S$175,1,FALSE)=$A40,"A",""),"") | E40: =IFERROR(IF(VLOOKUP($A40,T$2:T$175,1,FALSE)=$A40,"B",""),"") -> B | F40: =IFERROR(IF(VLOOKUP($A40,U$2:U$175,1,FALSE)=$A40,"C",""),"") | G40: =COUNTBLANK(B40:F40) -> 4 | Q40: ASTRALMAJESTY | U40: SNIPER
A41: MEGALAUNCHER | B41: =IFERROR(IF(VLOOKUP($A41,Q$2:Q$175,1,FALSE)=$A41,"S",""),"") | C41: =IFERROR(IF(VLOOKUP($A41,R$2:R$175,1,FALSE)=$A41,"D",""),"") | D41: =IFERROR(IF(VLOOKUP($A41,S$2:S$175,1,FALSE)=$A41,"A",""),"") -> A | E41: =IFERROR(IF(VLOOKUP($A41,T$2:T$175,1,FALSE)=$A41,"B",""),"") | F41: =IFERROR(IF(VLOOKUP($A41,U$2:U$175,1,FALSE)=$A41,"C",""),"") | G41: =COUNTBLANK(B41:F41) -> 4 | Q41: VENGEFUL | U41: STALL
A42: CLEARBODY | B42: =IFERROR(IF(VLOOKUP($A42,Q$2:Q$175,1,FALSE)=$A42,"S",""),"") | C42: =IFERROR(IF(VLOOKUP($A42,R$2:R$175,1,FALSE)=$A42,"D",""),"") | D42: =IFERROR(IF(VLOOKUP($A42,S$2:S$175,1,FALSE)=$A42,"A",""),"") -> A | E42: =IFERROR(IF(VLOOKUP($A42,T$2:T$175,1,FALSE)=$A42,"B",""),"") | F42: =IFERROR(IF(VLOOKUP($A42,U$2:U$175,1,FALSE)=$A42,"C",""),"") | G42: =COUNTBLANK(B42:F42) -> 4 | Q42: WINTERGIFT | U42: LEAFGUARD
A43: KEENEYE | B43: =IFERROR(IF(VLOOKUP($A43,Q$2:Q$175,1,FALSE)=$A43,"S",""),"") | C43: =IFERROR(IF(VLOOKUP($A43,R$2:R$175,1,FALSE)=$A43,"D",""),"") | D43: =IFERROR(IF(VLOOKUP($A43,S$2:S$175,1,FALSE)=$A43,"A",""),"") | E43: =IFERROR(IF(VLOOKUP($A43,T$2:T$175,1,FALSE)=$A43,"B",""),"") | F43: =IFERROR(IF(VLOOKUP($A43,U$2:U$175,1,FALSE)=$A43,"C",""),"") -> C | G43: =COUNTBLANK(B43:F43) -> 4 | Q43: DARKMATTER | U43: MOLDBREAKER
A44: ARENATRAP | B44: =IFERROR(IF(VLOOKUP($A44,Q$2:Q$175,1,FALSE)=$A44,"S",""),"") | C44: =IFERROR(IF(VLOOKUP($A44,R$2:R$175,1,FALSE)=$A44,"D",""),"") | D44: =IFERROR(IF(VLOOKUP($A44,S$2:S$175,1,FALSE)=$A44,"A",""),"") -> A | E44: =IFERROR(IF(VLOOKUP($A44,T$2:T$175,1,FALSE)=$A44,"B",""),"") | F44: =IFERROR(IF(VLOOKUP($A44,U$2:U$175,1,FALSE)=$A44,"C",""),"") | G44: =COUNTBLANK(B44:F44) -> 4 | Q44: LEADERSHIP | U44: AFTERMATH
A45: MOTORDRIVE | B45: =IFERROR(IF(VLOOKUP($A45,Q$2:Q$175,1,FALSE)=$A45,"S",""),"") -> S | C45: =IFERROR(IF(VLOOKUP($A45,R$2:R$175,1,FALSE)=$A45,"D",""),"") | D45: =IFERROR(IF(VLOOKUP($A45,S$2:S$175,1,FALSE)=$A45,"A",""),"") | E45: =IFERROR(IF(VLOOKUP($A45,T$2:T$175,1,FALSE)=$A45,"B",""),"") | F45: =IFERROR(IF(VLOOKUP($A45,U$2:U$175,1,FALSE)=$A45,"C",""),"") | G45: =COUNTBLANK(B45:F45) -> 4 | Q45: PACKEDSNOW | U45: FOREWARN
A46: STEADFAST | B46: =IFERROR(IF(VLOOKUP($A46,Q$2:Q$175,1,FALSE)=$A46,"S",""),"") | C46: =IFERROR(IF(VLOOKUP($A46,R$2:R$175,1,FALSE)=$A46,"D",""),"") | D46: =IFERROR(IF(VLOOKUP($A46,S$2:S$175,1,FALSE)=$A46,"A",""),"") | E46: =IFERROR(IF(VLOOKUP($A46,T$2:T$175,1,FALSE)=$A46,"B",""),"") | F46: =IFERROR(IF(VLOOKUP($A46,U$2:U$175,1,FALSE)=$A46,"C",""),"") -> C | G46: =COUNTBLANK(B46:F46) -> 4 | Q46: REALISM | U46: SLOWSTART
A47: TECHNICIAN | B47: =IFERROR(IF(VLOOKUP($A47,Q$2:Q$175,1,FALSE)=$A47,"S",""),"") | C47: =IFERROR(IF(VLOOKUP($A47,R$2:R$175,1,FALSE)=$A47,"D",""),"") | D47: =IFERROR(IF(VLOOKUP($A47,S$2:S$175,1,FALSE)=$A47,"A",""),"") -> A | E47: =IFERROR(IF(VLOOKUP($A47,T$2:T$175,1,FALSE)=$A47,"B",""),"") | F47: =IFERROR(IF(VLOOKUP($A47,U$2:U$175,1,FALSE)=$A47,"C",""),"") | G47: =COUNTBLANK(B47:F47) -> 4 | Q47: SHARPSHOOTER | U47: TELEPATHY
...
